File "/home/django-eccommerce/tokyotest/gunicorn.conf.py", line 3
    user = "nobody"bind = '127.0.0.1:8000'
                      ^
SyntaxError: invalid syntax
[2021-02-17 17:58:25 +0200] [16306] [INFO] Starting gunicorn 20.0.4
[2021-02-17 17:58:25 +0200] [16306] [INFO] Listening at: http://127.0.0.1:8000 (16306)
[2021-02-17 17:58:25 +0200] [16306] [INFO] Using worker: sync
[2021-02-17 17:58:25 +0200] [16310] [INFO] Booting worker with pid: 16310
[2021-02-17 17:58:25 +0200] [16312] [INFO] Booting worker with pid: 16312
[2021-02-17 17:58:25 +0200] [16313] [INFO] Booting worker with pid: 16313
Not Found: /shop/images/bg/dec/section-bg.png
Not Found: /delivery/images/bg/dec/section-bg.png
Not Found: /shop/images/bg/dec/section-bg.png
/home/venv/lib/python3.6/site-packages/django/views/generic/list.py:88: UnorderedObjectListWarning: Pagination may yield inconsistent results with an unordered object_list: <class 'core.models.Item'> QuerySet.
  allow_empty_first_page=allow_empty_first_page, **kwargs)
Internal Server Error: /
Traceback (most recent call last):
  File "/home/venv/lib/python3.6/site-packages/django/db/backends/utils.py", line 84, in _execute
    return self.cursor.execute(sql, params)
  File "/home/venv/lib/python3.6/site-packages/django/db/backends/sqlite3/base.py", line 413, in execute
    return Database.Cursor.execute(self, query, params)
sqlite3.OperationalError: attempt to write a readonly database

The above exception was the direct cause of the following exception:

Traceback (most recent call last):
  File "/home/venv/lib/python3.6/site-packages/django/core/handlers/exception.py", line 47, in inner
    response = get_response(request)
  File "/home/venv/lib/python3.6/site-packages/django/utils/deprecation.py", line 116, in __call__
    response = self.process_response(request, response)
  File "/home/venv/lib/python3.6/site-packages/django/contrib/sessions/middleware.py", line 63, in process_response
    request.session.save()
  File "/home/venv/lib/python3.6/site-packages/django/contrib/sessions/backends/db.py", line 81, in save
    return self.create()
  File "/home/venv/lib/python3.6/site-packages/django/contrib/sessions/backends/db.py", line 55, in create
    self.save(must_create=True)
  File "/home/venv/lib/python3.6/site-packages/django/contrib/sessions/backends/db.py", line 87, in save
    obj.save(force_insert=must_create, force_update=not must_create, using=using)
  File "/home/venv/lib/python3.6/site-packages/django/db/models/base.py", line 754, in save
    force_update=force_update, update_fields=update_fields)
  File "/home/venv/lib/python3.6/site-packages/django/db/models/base.py", line 792, in save_base
    force_update, using, update_fields,
  File "/home/venv/lib/python3.6/site-packages/django/db/models/base.py", line 895, in _save_table
    results = self._do_insert(cls._base_manager, using, fields, returning_fields, raw)
  File "/home/venv/lib/python3.6/site-packages/django/db/models/base.py", line 935, in _do_insert
    using=using, raw=raw,
  File "/home/venv/lib/python3.6/site-packages/django/db/models/manager.py", line 85, in manager_method
    return getattr(self.get_queryset(), name)(*args, **kwargs)
  File "/home/venv/lib/python3.6/site-packages/django/db/models/query.py", line 1249, in _insert
    return query.get_compiler(using=using).execute_sql(returning_fields)
  File "/home/venv/lib/python3.6/site-packages/django/db/models/sql/compiler.py", line 1397, in execute_sql
    cursor.execute(sql, params)
  File "/home/venv/lib/python3.6/site-packages/django/db/backends/utils.py", line 98, in execute
    return super().execute(sql, params)
  File "/home/venv/lib/python3.6/site-packages/django/db/backends/utils.py", line 66, in execute
    return self._execute_with_wrappers(sql, params, many=False, executor=self._execute)
  File "/home/venv/lib/python3.6/site-packages/django/db/backends/utils.py", line 75, in _execute_with_wrappers
    return executor(sql, params, many, context)
  File "/home/venv/lib/python3.6/site-packages/django/db/backends/utils.py", line 84, in _execute
    return self.cursor.execute(sql, params)
  File "/home/venv/lib/python3.6/site-packages/django/db/utils.py", line 90, in __exit__
    raise dj_exc_value.with_traceback(traceback) from exc_value
  File "/home/venv/lib/python3.6/site-packages/django/db/backends/utils.py", line 84, in _execute
    return self.cursor.execute(sql, params)
  File "/home/venv/lib/python3.6/site-packages/django/db/backends/sqlite3/base.py", line 413, in execute
    return Database.Cursor.execute(self, query, params)
django.db.utils.OperationalError: attempt to write a readonly database
Internal Server Error: /
Traceback (most recent call last):
  File "/home/venv/lib/python3.6/site-packages/django/db/backends/utils.py", line 84, in _execute
    return self.cursor.execute(sql, params)
  File "/home/venv/lib/python3.6/site-packages/django/db/backends/sqlite3/base.py", line 413, in execute
    return Database.Cursor.execute(self, query, params)
sqlite3.OperationalError: attempt to write a readonly database

The above exception was the direct cause of the following exception:

Traceback (most recent call last):
  File "/home/venv/lib/python3.6/site-packages/django/core/handlers/exception.py", line 47, in inner
    response = get_response(request)
  File "/home/venv/lib/python3.6/site-packages/django/utils/deprecation.py", line 116, in __call__
    response = self.process_response(request, response)
  File "/home/venv/lib/python3.6/site-packages/django/contrib/sessions/middleware.py", line 63, in process_response
    request.session.save()
  File "/home/venv/lib/python3.6/site-packages/django/contrib/sessions/backends/db.py", line 81, in save
    return self.create()
  File "/home/venv/lib/python3.6/site-packages/django/contrib/sessions/backends/db.py", line 55, in create
    self.save(must_create=True)
  File "/home/venv/lib/python3.6/site-packages/django/contrib/sessions/backends/db.py", line 87, in save
    obj.save(force_insert=must_create, force_update=not must_create, using=using)
  File "/home/venv/lib/python3.6/site-packages/django/db/models/base.py", line 754, in save
    force_update=force_update, update_fields=update_fields)
  File "/home/venv/lib/python3.6/site-packages/django/db/models/base.py", line 792, in save_base
    force_update, using, update_fields,
  File "/home/venv/lib/python3.6/site-packages/django/db/models/base.py", line 895, in _save_table
    results = self._do_insert(cls._base_manager, using, fields, returning_fields, raw)
  File "/home/venv/lib/python3.6/site-packages/django/db/models/base.py", line 935, in _do_insert
    using=using, raw=raw,
  File "/home/venv/lib/python3.6/site-packages/django/db/models/manager.py", line 85, in manager_method
    return getattr(self.get_queryset(), name)(*args, **kwargs)
  File "/home/venv/lib/python3.6/site-packages/django/db/models/query.py", line 1249, in _insert
    return query.get_compiler(using=using).execute_sql(returning_fields)
  File "/home/venv/lib/python3.6/site-packages/django/db/models/sql/compiler.py", line 1397, in execute_sql
    cursor.execute(sql, params)
  File "/home/venv/lib/python3.6/site-packages/django/db/backends/utils.py", line 98, in execute
    return super().execute(sql, params)
  File "/home/venv/lib/python3.6/site-packages/django/db/backends/utils.py", line 66, in execute
    return self._execute_with_wrappers(sql, params, many=False, executor=self._execute)
  File "/home/venv/lib/python3.6/site-packages/django/db/backends/utils.py", line 75, in _execute_with_wrappers
    return executor(sql, params, many, context)
  File "/home/venv/lib/python3.6/site-packages/django/db/backends/utils.py", line 84, in _execute
    return self.cursor.execute(sql, params)
  File "/home/venv/lib/python3.6/site-packages/django/db/utils.py", line 90, in __exit__
    raise dj_exc_value.with_traceback(traceback) from exc_value
  File "/home/venv/lib/python3.6/site-packages/django/db/backends/utils.py", line 84, in _execute
    return self.cursor.execute(sql, params)
  File "/home/venv/lib/python3.6/site-packages/django/db/backends/sqlite3/base.py", line 413, in execute
    return Database.Cursor.execute(self, query, params)
django.db.utils.OperationalError: attempt to write a readonly database
Not Found: /wp-content/themes/dark/js/scripts.js
Not Found: /wp-content/themes/dark/images/logo.png
Not Found: /wp-content/themes/dark/css/dark-style.css
Not Found: /wp-content/themes/dark/css/reset.css
Not Found: /wp-content/themes/dark/js/plugins.js
Not Found: /wp-content/themes/dark/fonts/fa-brands-400.woff2
Not Found: /wp-content/themes/dark/fonts/fa-solid-900.woff2
Not Found: /wp-content/themes/dark/fonts/fa-regular-400.woff2
Not Found: /wp-content/themes/dark/images/cube.png
Not Found: /wp-content/themes/dark/images/signature.png
Not Found: /wp-content/themes/dark/images/avatar/1.jpg
Not Found: /wp-content/themes/dark/images/logo2.png
Not Found: /wp-content/themes/dark/images/team/1.jpg
Not Found: /wp-content/themes/dark/images/ink2.png
Not Found: /wp-content/themes/dark/images/bg/dec/section-bg.png
Not Found: /wp-content/themes/dark/images/bg/dec/7.png
Not Found: /wp-content/themes/dark/images/wave.png
Not Found: /delivery/images/bg/dec/section-bg.png
Not Found: /.env
Forbidden (CSRF cookie not set.): /
Internal Server Error: /
Traceback (most recent call last):
  File "/home/venv/lib/python3.6/site-packages/django/db/backends/utils.py", line 84, in _execute
    return self.cursor.execute(sql, params)
  File "/home/venv/lib/python3.6/site-packages/django/db/backends/sqlite3/base.py", line 413, in execute
    return Database.Cursor.execute(self, query, params)
sqlite3.OperationalError: attempt to write a readonly database

The above exception was the direct cause of the following exception:

Traceback (most recent call last):
  File "/home/venv/lib/python3.6/site-packages/django/core/handlers/exception.py", line 47, in inner
    response = get_response(request)
  File "/home/venv/lib/python3.6/site-packages/django/utils/deprecation.py", line 116, in __call__
    response = self.process_response(request, response)
  File "/home/venv/lib/python3.6/site-packages/django/contrib/sessions/middleware.py", line 63, in process_response
    request.session.save()
  File "/home/venv/lib/python3.6/site-packages/django/contrib/sessions/backends/db.py", line 81, in save
    return self.create()
  File "/home/venv/lib/python3.6/site-packages/django/contrib/sessions/backends/db.py", line 55, in create
    self.save(must_create=True)
  File "/home/venv/lib/python3.6/site-packages/django/contrib/sessions/backends/db.py", line 87, in save
    obj.save(force_insert=must_create, force_update=not must_create, using=using)
  File "/home/venv/lib/python3.6/site-packages/django/db/models/base.py", line 754, in save
    force_update=force_update, update_fields=update_fields)
  File "/home/venv/lib/python3.6/site-packages/django/db/models/base.py", line 792, in save_base
    force_update, using, update_fields,
  File "/home/venv/lib/python3.6/site-packages/django/db/models/base.py", line 895, in _save_table
    results = self._do_insert(cls._base_manager, using, fields, returning_fields, raw)
  File "/home/venv/lib/python3.6/site-packages/django/db/models/base.py", line 935, in _do_insert
    using=using, raw=raw,
  File "/home/venv/lib/python3.6/site-packages/django/db/models/manager.py", line 85, in manager_method
    return getattr(self.get_queryset(), name)(*args, **kwargs)
  File "/home/venv/lib/python3.6/site-packages/django/db/models/query.py", line 1249, in _insert
    return query.get_compiler(using=using).execute_sql(returning_fields)
  File "/home/venv/lib/python3.6/site-packages/django/db/models/sql/compiler.py", line 1397, in execute_sql
    cursor.execute(sql, params)
  File "/home/venv/lib/python3.6/site-packages/django/db/backends/utils.py", line 98, in execute
    return super().execute(sql, params)
  File "/home/venv/lib/python3.6/site-packages/django/db/backends/utils.py", line 66, in execute
    return self._execute_with_wrappers(sql, params, many=False, executor=self._execute)
  File "/home/venv/lib/python3.6/site-packages/django/db/backends/utils.py", line 75, in _execute_with_wrappers
    return executor(sql, params, many, context)
  File "/home/venv/lib/python3.6/site-packages/django/db/backends/utils.py", line 84, in _execute
    return self.cursor.execute(sql, params)
  File "/home/venv/lib/python3.6/site-packages/django/db/utils.py", line 90, in __exit__
    raise dj_exc_value.with_traceback(traceback) from exc_value
  File "/home/venv/lib/python3.6/site-packages/django/db/backends/utils.py", line 84, in _execute
    return self.cursor.execute(sql, params)
  File "/home/venv/lib/python3.6/site-packages/django/db/backends/sqlite3/base.py", line 413, in execute
    return Database.Cursor.execute(self, query, params)
django.db.utils.OperationalError: attempt to write a readonly database
Internal Server Error: /
Traceback (most recent call last):
  File "/home/venv/lib/python3.6/site-packages/django/db/backends/utils.py", line 84, in _execute
    return self.cursor.execute(sql, params)
  File "/home/venv/lib/python3.6/site-packages/django/db/backends/sqlite3/base.py", line 413, in execute
    return Database.Cursor.execute(self, query, params)
sqlite3.OperationalError: attempt to write a readonly database

The above exception was the direct cause of the following exception:

Traceback (most recent call last):
  File "/home/venv/lib/python3.6/site-packages/django/core/handlers/exception.py", line 47, in inner
    response = get_response(request)
  File "/home/venv/lib/python3.6/site-packages/django/utils/deprecation.py", line 116, in __call__
    response = self.process_response(request, response)
  File "/home/venv/lib/python3.6/site-packages/django/contrib/sessions/middleware.py", line 63, in process_response
    request.session.save()
  File "/home/venv/lib/python3.6/site-packages/django/contrib/sessions/backends/db.py", line 81, in save
    return self.create()
  File "/home/venv/lib/python3.6/site-packages/django/contrib/sessions/backends/db.py", line 55, in create
    self.save(must_create=True)
  File "/home/venv/lib/python3.6/site-packages/django/contrib/sessions/backends/db.py", line 87, in save
    obj.save(force_insert=must_create, force_update=not must_create, using=using)
  File "/home/venv/lib/python3.6/site-packages/django/db/models/base.py", line 754, in save
    force_update=force_update, update_fields=update_fields)
  File "/home/venv/lib/python3.6/site-packages/django/db/models/base.py", line 792, in save_base
    force_update, using, update_fields,
  File "/home/venv/lib/python3.6/site-packages/django/db/models/base.py", line 895, in _save_table
    results = self._do_insert(cls._base_manager, using, fields, returning_fields, raw)
  File "/home/venv/lib/python3.6/site-packages/django/db/models/base.py", line 935, in _do_insert
    using=using, raw=raw,
  File "/home/venv/lib/python3.6/site-packages/django/db/models/manager.py", line 85, in manager_method
    return getattr(self.get_queryset(), name)(*args, **kwargs)
  File "/home/venv/lib/python3.6/site-packages/django/db/models/query.py", line 1249, in _insert
    return query.get_compiler(using=using).execute_sql(returning_fields)
  File "/home/venv/lib/python3.6/site-packages/django/db/models/sql/compiler.py", line 1397, in execute_sql
    cursor.execute(sql, params)
  File "/home/venv/lib/python3.6/site-packages/django/db/backends/utils.py", line 98, in execute
    return super().execute(sql, params)
  File "/home/venv/lib/python3.6/site-packages/django/db/backends/utils.py", line 66, in execute
    return self._execute_with_wrappers(sql, params, many=False, executor=self._execute)
  File "/home/venv/lib/python3.6/site-packages/django/db/backends/utils.py", line 75, in _execute_with_wrappers
    return executor(sql, params, many, context)
  File "/home/venv/lib/python3.6/site-packages/django/db/backends/utils.py", line 84, in _execute
    return self.cursor.execute(sql, params)
  File "/home/venv/lib/python3.6/site-packages/django/db/utils.py", line 90, in __exit__
    raise dj_exc_value.with_traceback(traceback) from exc_value
  File "/home/venv/lib/python3.6/site-packages/django/db/backends/utils.py", line 84, in _execute
    return self.cursor.execute(sql, params)
  File "/home/venv/lib/python3.6/site-packages/django/db/backends/sqlite3/base.py", line 413, in execute
    return Database.Cursor.execute(self, query, params)
django.db.utils.OperationalError: attempt to write a readonly database
Internal Server Error: /
Traceback (most recent call last):
  File "/home/venv/lib/python3.6/site-packages/django/db/backends/utils.py", line 84, in _execute
    return self.cursor.execute(sql, params)
  File "/home/venv/lib/python3.6/site-packages/django/db/backends/sqlite3/base.py", line 413, in execute
    return Database.Cursor.execute(self, query, params)
sqlite3.OperationalError: attempt to write a readonly database

The above exception was the direct cause of the following exception:

Traceback (most recent call last):
  File "/home/venv/lib/python3.6/site-packages/django/core/handlers/exception.py", line 47, in inner
    response = get_response(request)
  File "/home/venv/lib/python3.6/site-packages/django/utils/deprecation.py", line 116, in __call__
    response = self.process_response(request, response)
  File "/home/venv/lib/python3.6/site-packages/django/contrib/sessions/middleware.py", line 63, in process_response
    request.session.save()
  File "/home/venv/lib/python3.6/site-packages/django/contrib/sessions/backends/db.py", line 81, in save
    return self.create()
  File "/home/venv/lib/python3.6/site-packages/django/contrib/sessions/backends/db.py", line 55, in create
    self.save(must_create=True)
  File "/home/venv/lib/python3.6/site-packages/django/contrib/sessions/backends/db.py", line 87, in save
    obj.save(force_insert=must_create, force_update=not must_create, using=using)
  File "/home/venv/lib/python3.6/site-packages/django/db/models/base.py", line 754, in save
    force_update=force_update, update_fields=update_fields)
  File "/home/venv/lib/python3.6/site-packages/django/db/models/base.py", line 792, in save_base
    force_update, using, update_fields,
  File "/home/venv/lib/python3.6/site-packages/django/db/models/base.py", line 895, in _save_table
    results = self._do_insert(cls._base_manager, using, fields, returning_fields, raw)
  File "/home/venv/lib/python3.6/site-packages/django/db/models/base.py", line 935, in _do_insert
    using=using, raw=raw,
  File "/home/venv/lib/python3.6/site-packages/django/db/models/manager.py", line 85, in manager_method
    return getattr(self.get_queryset(), name)(*args, **kwargs)
  File "/home/venv/lib/python3.6/site-packages/django/db/models/query.py", line 1249, in _insert
    return query.get_compiler(using=using).execute_sql(returning_fields)
  File "/home/venv/lib/python3.6/site-packages/django/db/models/sql/compiler.py", line 1397, in execute_sql
    cursor.execute(sql, params)
  File "/home/venv/lib/python3.6/site-packages/django/db/backends/utils.py", line 98, in execute
    return super().execute(sql, params)
  File "/home/venv/lib/python3.6/site-packages/django/db/backends/utils.py", line 66, in execute
    return self._execute_with_wrappers(sql, params, many=False, executor=self._execute)
  File "/home/venv/lib/python3.6/site-packages/django/db/backends/utils.py", line 75, in _execute_with_wrappers
    return executor(sql, params, many, context)
  File "/home/venv/lib/python3.6/site-packages/django/db/backends/utils.py", line 84, in _execute
    return self.cursor.execute(sql, params)
  File "/home/venv/lib/python3.6/site-packages/django/db/utils.py", line 90, in __exit__
    raise dj_exc_value.with_traceback(traceback) from exc_value
  File "/home/venv/lib/python3.6/site-packages/django/db/backends/utils.py", line 84, in _execute
    return self.cursor.execute(sql, params)
  File "/home/venv/lib/python3.6/site-packages/django/db/backends/sqlite3/base.py", line 413, in execute
    return Database.Cursor.execute(self, query, params)
django.db.utils.OperationalError: attempt to write a readonly database
Not Found: /favicon.ico
Internal Server Error: /
Traceback (most recent call last):
  File "/home/venv/lib/python3.6/site-packages/django/db/backends/utils.py", line 84, in _execute
    return self.cursor.execute(sql, params)
  File "/home/venv/lib/python3.6/site-packages/django/db/backends/sqlite3/base.py", line 413, in execute
    return Database.Cursor.execute(self, query, params)
sqlite3.OperationalError: attempt to write a readonly database

The above exception was the direct cause of the following exception:

Traceback (most recent call last):
  File "/home/venv/lib/python3.6/site-packages/django/core/handlers/exception.py", line 47, in inner
    response = get_response(request)
  File "/home/venv/lib/python3.6/site-packages/django/utils/deprecation.py", line 116, in __call__
    response = self.process_response(request, response)
  File "/home/venv/lib/python3.6/site-packages/django/contrib/sessions/middleware.py", line 63, in process_response
    request.session.save()
  File "/home/venv/lib/python3.6/site-packages/django/contrib/sessions/backends/db.py", line 81, in save
    return self.create()
  File "/home/venv/lib/python3.6/site-packages/django/contrib/sessions/backends/db.py", line 55, in create
    self.save(must_create=True)
  File "/home/venv/lib/python3.6/site-packages/django/contrib/sessions/backends/db.py", line 87, in save
    obj.save(force_insert=must_create, force_update=not must_create, using=using)
  File "/home/venv/lib/python3.6/site-packages/django/db/models/base.py", line 754, in save
    force_update=force_update, update_fields=update_fields)
  File "/home/venv/lib/python3.6/site-packages/django/db/models/base.py", line 792, in save_base
    force_update, using, update_fields,
  File "/home/venv/lib/python3.6/site-packages/django/db/models/base.py", line 895, in _save_table
    results = self._do_insert(cls._base_manager, using, fields, returning_fields, raw)
  File "/home/venv/lib/python3.6/site-packages/django/db/models/base.py", line 935, in _do_insert
    using=using, raw=raw,
  File "/home/venv/lib/python3.6/site-packages/django/db/models/manager.py", line 85, in manager_method
    return getattr(self.get_queryset(), name)(*args, **kwargs)
  File "/home/venv/lib/python3.6/site-packages/django/db/models/query.py", line 1249, in _insert
    return query.get_compiler(using=using).execute_sql(returning_fields)
  File "/home/venv/lib/python3.6/site-packages/django/db/models/sql/compiler.py", line 1397, in execute_sql
    cursor.execute(sql, params)
  File "/home/venv/lib/python3.6/site-packages/django/db/backends/utils.py", line 98, in execute
    return super().execute(sql, params)
  File "/home/venv/lib/python3.6/site-packages/django/db/backends/utils.py", line 66, in execute
    return self._execute_with_wrappers(sql, params, many=False, executor=self._execute)
  File "/home/venv/lib/python3.6/site-packages/django/db/backends/utils.py", line 75, in _execute_with_wrappers
    return executor(sql, params, many, context)
  File "/home/venv/lib/python3.6/site-packages/django/db/backends/utils.py", line 84, in _execute
    return self.cursor.execute(sql, params)
  File "/home/venv/lib/python3.6/site-packages/django/db/utils.py", line 90, in __exit__
    raise dj_exc_value.with_traceback(traceback) from exc_value
  File "/home/venv/lib/python3.6/site-packages/django/db/backends/utils.py", line 84, in _execute
    return self.cursor.execute(sql, params)
  File "/home/venv/lib/python3.6/site-packages/django/db/backends/sqlite3/base.py", line 413, in execute
    return Database.Cursor.execute(self, query, params)
django.db.utils.OperationalError: attempt to write a readonly database
Internal Server Error: /
Traceback (most recent call last):
  File "/home/venv/lib/python3.6/site-packages/django/db/backends/utils.py", line 84, in _execute
    return self.cursor.execute(sql, params)
  File "/home/venv/lib/python3.6/site-packages/django/db/backends/sqlite3/base.py", line 413, in execute
    return Database.Cursor.execute(self, query, params)
sqlite3.OperationalError: attempt to write a readonly database

The above exception was the direct cause of the following exception:

Traceback (most recent call last):
  File "/home/venv/lib/python3.6/site-packages/django/core/handlers/exception.py", line 47, in inner
    response = get_response(request)
  File "/home/venv/lib/python3.6/site-packages/django/utils/deprecation.py", line 116, in __call__
    response = self.process_response(request, response)
  File "/home/venv/lib/python3.6/site-packages/django/contrib/sessions/middleware.py", line 63, in process_response
    request.session.save()
  File "/home/venv/lib/python3.6/site-packages/django/contrib/sessions/backends/db.py", line 81, in save
    return self.create()
  File "/home/venv/lib/python3.6/site-packages/django/contrib/sessions/backends/db.py", line 55, in create
    self.save(must_create=True)
  File "/home/venv/lib/python3.6/site-packages/django/contrib/sessions/backends/db.py", line 87, in save
    obj.save(force_insert=must_create, force_update=not must_create, using=using)
  File "/home/venv/lib/python3.6/site-packages/django/db/models/base.py", line 754, in save
    force_update=force_update, update_fields=update_fields)
  File "/home/venv/lib/python3.6/site-packages/django/db/models/base.py", line 792, in save_base
    force_update, using, update_fields,
  File "/home/venv/lib/python3.6/site-packages/django/db/models/base.py", line 895, in _save_table
    results = self._do_insert(cls._base_manager, using, fields, returning_fields, raw)
  File "/home/venv/lib/python3.6/site-packages/django/db/models/base.py", line 935, in _do_insert
    using=using, raw=raw,
  File "/home/venv/lib/python3.6/site-packages/django/db/models/manager.py", line 85, in manager_method
    return getattr(self.get_queryset(), name)(*args, **kwargs)
  File "/home/venv/lib/python3.6/site-packages/django/db/models/query.py", line 1249, in _insert
    return query.get_compiler(using=using).execute_sql(returning_fields)
  File "/home/venv/lib/python3.6/site-packages/django/db/models/sql/compiler.py", line 1397, in execute_sql
    cursor.execute(sql, params)
  File "/home/venv/lib/python3.6/site-packages/django/db/backends/utils.py", line 98, in execute
    return super().execute(sql, params)
  File "/home/venv/lib/python3.6/site-packages/django/db/backends/utils.py", line 66, in execute
    return self._execute_with_wrappers(sql, params, many=False, executor=self._execute)
  File "/home/venv/lib/python3.6/site-packages/django/db/backends/utils.py", line 75, in _execute_with_wrappers
    return executor(sql, params, many, context)
  File "/home/venv/lib/python3.6/site-packages/django/db/backends/utils.py", line 84, in _execute
    return self.cursor.execute(sql, params)
  File "/home/venv/lib/python3.6/site-packages/django/db/utils.py", line 90, in __exit__
    raise dj_exc_value.with_traceback(traceback) from exc_value
  File "/home/venv/lib/python3.6/site-packages/django/db/backends/utils.py", line 84, in _execute
    return self.cursor.execute(sql, params)
  File "/home/venv/lib/python3.6/site-packages/django/db/backends/sqlite3/base.py", line 413, in execute
    return Database.Cursor.execute(self, query, params)
django.db.utils.OperationalError: attempt to write a readonly database
Not Found: /favicon.ico
Internal Server Error: /
Traceback (most recent call last):
  File "/home/venv/lib/python3.6/site-packages/django/db/backends/utils.py", line 84, in _execute
    return self.cursor.execute(sql, params)
  File "/home/venv/lib/python3.6/site-packages/django/db/backends/sqlite3/base.py", line 413, in execute
    return Database.Cursor.execute(self, query, params)
sqlite3.OperationalError: attempt to write a readonly database

The above exception was the direct cause of the following exception:

Traceback (most recent call last):
  File "/home/venv/lib/python3.6/site-packages/django/core/handlers/exception.py", line 47, in inner
    response = get_response(request)
  File "/home/venv/lib/python3.6/site-packages/django/utils/deprecation.py", line 116, in __call__
    response = self.process_response(request, response)
  File "/home/venv/lib/python3.6/site-packages/django/contrib/sessions/middleware.py", line 63, in process_response
    request.session.save()
  File "/home/venv/lib/python3.6/site-packages/django/contrib/sessions/backends/db.py", line 81, in save
    return self.create()
  File "/home/venv/lib/python3.6/site-packages/django/contrib/sessions/backends/db.py", line 55, in create
    self.save(must_create=True)
  File "/home/venv/lib/python3.6/site-packages/django/contrib/sessions/backends/db.py", line 87, in save
    obj.save(force_insert=must_create, force_update=not must_create, using=using)
  File "/home/venv/lib/python3.6/site-packages/django/db/models/base.py", line 754, in save
    force_update=force_update, update_fields=update_fields)
  File "/home/venv/lib/python3.6/site-packages/django/db/models/base.py", line 792, in save_base
    force_update, using, update_fields,
  File "/home/venv/lib/python3.6/site-packages/django/db/models/base.py", line 895, in _save_table
    results = self._do_insert(cls._base_manager, using, fields, returning_fields, raw)
  File "/home/venv/lib/python3.6/site-packages/django/db/models/base.py", line 935, in _do_insert
    using=using, raw=raw,
  File "/home/venv/lib/python3.6/site-packages/django/db/models/manager.py", line 85, in manager_method
    return getattr(self.get_queryset(), name)(*args, **kwargs)
  File "/home/venv/lib/python3.6/site-packages/django/db/models/query.py", line 1249, in _insert
    return query.get_compiler(using=using).execute_sql(returning_fields)
  File "/home/venv/lib/python3.6/site-packages/django/db/models/sql/compiler.py", line 1397, in execute_sql
    cursor.execute(sql, params)
  File "/home/venv/lib/python3.6/site-packages/django/db/backends/utils.py", line 98, in execute
    return super().execute(sql, params)
  File "/home/venv/lib/python3.6/site-packages/django/db/backends/utils.py", line 66, in execute
    return self._execute_with_wrappers(sql, params, many=False, executor=self._execute)
  File "/home/venv/lib/python3.6/site-packages/django/db/backends/utils.py", line 75, in _execute_with_wrappers
    return executor(sql, params, many, context)
  File "/home/venv/lib/python3.6/site-packages/django/db/backends/utils.py", line 84, in _execute
    return self.cursor.execute(sql, params)
  File "/home/venv/lib/python3.6/site-packages/django/db/utils.py", line 90, in __exit__
    raise dj_exc_value.with_traceback(traceback) from exc_value
  File "/home/venv/lib/python3.6/site-packages/django/db/backends/utils.py", line 84, in _execute
    return self.cursor.execute(sql, params)
  File "/home/venv/lib/python3.6/site-packages/django/db/backends/sqlite3/base.py", line 413, in execute
    return Database.Cursor.execute(self, query, params)
django.db.utils.OperationalError: attempt to write a readonly database
Internal Server Error: /
Traceback (most recent call last):
  File "/home/venv/lib/python3.6/site-packages/django/db/backends/utils.py", line 84, in _execute
    return self.cursor.execute(sql, params)
  File "/home/venv/lib/python3.6/site-packages/django/db/backends/sqlite3/base.py", line 413, in execute
    return Database.Cursor.execute(self, query, params)
sqlite3.OperationalError: attempt to write a readonly database

The above exception was the direct cause of the following exception:

Traceback (most recent call last):
  File "/home/venv/lib/python3.6/site-packages/django/core/handlers/exception.py", line 47, in inner
    response = get_response(request)
  File "/home/venv/lib/python3.6/site-packages/django/utils/deprecation.py", line 116, in __call__
    response = self.process_response(request, response)
  File "/home/venv/lib/python3.6/site-packages/django/contrib/sessions/middleware.py", line 63, in process_response
    request.session.save()
  File "/home/venv/lib/python3.6/site-packages/django/contrib/sessions/backends/db.py", line 81, in save
    return self.create()
  File "/home/venv/lib/python3.6/site-packages/django/contrib/sessions/backends/db.py", line 55, in create
    self.save(must_create=True)
  File "/home/venv/lib/python3.6/site-packages/django/contrib/sessions/backends/db.py", line 87, in save
    obj.save(force_insert=must_create, force_update=not must_create, using=using)
  File "/home/venv/lib/python3.6/site-packages/django/db/models/base.py", line 754, in save
    force_update=force_update, update_fields=update_fields)
  File "/home/venv/lib/python3.6/site-packages/django/db/models/base.py", line 792, in save_base
    force_update, using, update_fields,
  File "/home/venv/lib/python3.6/site-packages/django/db/models/base.py", line 895, in _save_table
    results = self._do_insert(cls._base_manager, using, fields, returning_fields, raw)
  File "/home/venv/lib/python3.6/site-packages/django/db/models/base.py", line 935, in _do_insert
    using=using, raw=raw,
  File "/home/venv/lib/python3.6/site-packages/django/db/models/manager.py", line 85, in manager_method
    return getattr(self.get_queryset(), name)(*args, **kwargs)
  File "/home/venv/lib/python3.6/site-packages/django/db/models/query.py", line 1249, in _insert
    return query.get_compiler(using=using).execute_sql(returning_fields)
  File "/home/venv/lib/python3.6/site-packages/django/db/models/sql/compiler.py", line 1397, in execute_sql
    cursor.execute(sql, params)
  File "/home/venv/lib/python3.6/site-packages/django/db/backends/utils.py", line 98, in execute
    return super().execute(sql, params)
  File "/home/venv/lib/python3.6/site-packages/django/db/backends/utils.py", line 66, in execute
    return self._execute_with_wrappers(sql, params, many=False, executor=self._execute)
  File "/home/venv/lib/python3.6/site-packages/django/db/backends/utils.py", line 75, in _execute_with_wrappers
    return executor(sql, params, many, context)
  File "/home/venv/lib/python3.6/site-packages/django/db/backends/utils.py", line 84, in _execute
    return self.cursor.execute(sql, params)
  File "/home/venv/lib/python3.6/site-packages/django/db/utils.py", line 90, in __exit__
    raise dj_exc_value.with_traceback(traceback) from exc_value
  File "/home/venv/lib/python3.6/site-packages/django/db/backends/utils.py", line 84, in _execute
    return self.cursor.execute(sql, params)
  File "/home/venv/lib/python3.6/site-packages/django/db/backends/sqlite3/base.py", line 413, in execute
    return Database.Cursor.execute(self, query, params)
django.db.utils.OperationalError: attempt to write a readonly database
Not Found: /favicon.ico
Internal Server Error: /
Traceback (most recent call last):
  File "/home/venv/lib/python3.6/site-packages/django/db/backends/utils.py", line 84, in _execute
    return self.cursor.execute(sql, params)
  File "/home/venv/lib/python3.6/site-packages/django/db/backends/sqlite3/base.py", line 413, in execute
    return Database.Cursor.execute(self, query, params)
sqlite3.OperationalError: attempt to write a readonly database

The above exception was the direct cause of the following exception:

Traceback (most recent call last):
  File "/home/venv/lib/python3.6/site-packages/django/core/handlers/exception.py", line 47, in inner
    response = get_response(request)
  File "/home/venv/lib/python3.6/site-packages/django/utils/deprecation.py", line 116, in __call__
    response = self.process_response(request, response)
  File "/home/venv/lib/python3.6/site-packages/django/contrib/sessions/middleware.py", line 63, in process_response
    request.session.save()
  File "/home/venv/lib/python3.6/site-packages/django/contrib/sessions/backends/db.py", line 81, in save
    return self.create()
  File "/home/venv/lib/python3.6/site-packages/django/contrib/sessions/backends/db.py", line 55, in create
    self.save(must_create=True)
  File "/home/venv/lib/python3.6/site-packages/django/contrib/sessions/backends/db.py", line 87, in save
    obj.save(force_insert=must_create, force_update=not must_create, using=using)
  File "/home/venv/lib/python3.6/site-packages/django/db/models/base.py", line 754, in save
    force_update=force_update, update_fields=update_fields)
  File "/home/venv/lib/python3.6/site-packages/django/db/models/base.py", line 792, in save_base
    force_update, using, update_fields,
  File "/home/venv/lib/python3.6/site-packages/django/db/models/base.py", line 895, in _save_table
    results = self._do_insert(cls._base_manager, using, fields, returning_fields, raw)
  File "/home/venv/lib/python3.6/site-packages/django/db/models/base.py", line 935, in _do_insert
    using=using, raw=raw,
  File "/home/venv/lib/python3.6/site-packages/django/db/models/manager.py", line 85, in manager_method
    return getattr(self.get_queryset(), name)(*args, **kwargs)
  File "/home/venv/lib/python3.6/site-packages/django/db/models/query.py", line 1249, in _insert
    return query.get_compiler(using=using).execute_sql(returning_fields)
  File "/home/venv/lib/python3.6/site-packages/django/db/models/sql/compiler.py", line 1397, in execute_sql
    cursor.execute(sql, params)
  File "/home/venv/lib/python3.6/site-packages/django/db/backends/utils.py", line 98, in execute
    return super().execute(sql, params)
  File "/home/venv/lib/python3.6/site-packages/django/db/backends/utils.py", line 66, in execute
    return self._execute_with_wrappers(sql, params, many=False, executor=self._execute)
  File "/home/venv/lib/python3.6/site-packages/django/db/backends/utils.py", line 75, in _execute_with_wrappers
    return executor(sql, params, many, context)
  File "/home/venv/lib/python3.6/site-packages/django/db/backends/utils.py", line 84, in _execute
    return self.cursor.execute(sql, params)
  File "/home/venv/lib/python3.6/site-packages/django/db/utils.py", line 90, in __exit__
    raise dj_exc_value.with_traceback(traceback) from exc_value
  File "/home/venv/lib/python3.6/site-packages/django/db/backends/utils.py", line 84, in _execute
    return self.cursor.execute(sql, params)
  File "/home/venv/lib/python3.6/site-packages/django/db/backends/sqlite3/base.py", line 413, in execute
    return Database.Cursor.execute(self, query, params)
django.db.utils.OperationalError: attempt to write a readonly database
Internal Server Error: /
Traceback (most recent call last):
  File "/home/venv/lib/python3.6/site-packages/django/db/backends/utils.py", line 84, in _execute
    return self.cursor.execute(sql, params)
  File "/home/venv/lib/python3.6/site-packages/django/db/backends/sqlite3/base.py", line 413, in execute
    return Database.Cursor.execute(self, query, params)
sqlite3.OperationalError: attempt to write a readonly database

The above exception was the direct cause of the following exception:

Traceback (most recent call last):
  File "/home/venv/lib/python3.6/site-packages/django/core/handlers/exception.py", line 47, in inner
    response = get_response(request)
  File "/home/venv/lib/python3.6/site-packages/django/utils/deprecation.py", line 116, in __call__
    response = self.process_response(request, response)
  File "/home/venv/lib/python3.6/site-packages/django/contrib/sessions/middleware.py", line 63, in process_response
    request.session.save()
  File "/home/venv/lib/python3.6/site-packages/django/contrib/sessions/backends/db.py", line 81, in save
    return self.create()
  File "/home/venv/lib/python3.6/site-packages/django/contrib/sessions/backends/db.py", line 55, in create
    self.save(must_create=True)
  File "/home/venv/lib/python3.6/site-packages/django/contrib/sessions/backends/db.py", line 87, in save
    obj.save(force_insert=must_create, force_update=not must_create, using=using)
  File "/home/venv/lib/python3.6/site-packages/django/db/models/base.py", line 754, in save
    force_update=force_update, update_fields=update_fields)
  File "/home/venv/lib/python3.6/site-packages/django/db/models/base.py", line 792, in save_base
    force_update, using, update_fields,
  File "/home/venv/lib/python3.6/site-packages/django/db/models/base.py", line 895, in _save_table
    results = self._do_insert(cls._base_manager, using, fields, returning_fields, raw)
  File "/home/venv/lib/python3.6/site-packages/django/db/models/base.py", line 935, in _do_insert
    using=using, raw=raw,
  File "/home/venv/lib/python3.6/site-packages/django/db/models/manager.py", line 85, in manager_method
    return getattr(self.get_queryset(), name)(*args, **kwargs)
  File "/home/venv/lib/python3.6/site-packages/django/db/models/query.py", line 1249, in _insert
    return query.get_compiler(using=using).execute_sql(returning_fields)
  File "/home/venv/lib/python3.6/site-packages/django/db/models/sql/compiler.py", line 1397, in execute_sql
    cursor.execute(sql, params)
  File "/home/venv/lib/python3.6/site-packages/django/db/backends/utils.py", line 98, in execute
    return super().execute(sql, params)
  File "/home/venv/lib/python3.6/site-packages/django/db/backends/utils.py", line 66, in execute
    return self._execute_with_wrappers(sql, params, many=False, executor=self._execute)
  File "/home/venv/lib/python3.6/site-packages/django/db/backends/utils.py", line 75, in _execute_with_wrappers
    return executor(sql, params, many, context)
  File "/home/venv/lib/python3.6/site-packages/django/db/backends/utils.py", line 84, in _execute
    return self.cursor.execute(sql, params)
  File "/home/venv/lib/python3.6/site-packages/django/db/utils.py", line 90, in __exit__
    raise dj_exc_value.with_traceback(traceback) from exc_value
  File "/home/venv/lib/python3.6/site-packages/django/db/backends/utils.py", line 84, in _execute
    return self.cursor.execute(sql, params)
  File "/home/venv/lib/python3.6/site-packages/django/db/backends/sqlite3/base.py", line 413, in execute
    return Database.Cursor.execute(self, query, params)
django.db.utils.OperationalError: attempt to write a readonly database
Internal Server Error: /
Traceback (most recent call last):
  File "/home/venv/lib/python3.6/site-packages/django/db/backends/utils.py", line 84, in _execute
    return self.cursor.execute(sql, params)
  File "/home/venv/lib/python3.6/site-packages/django/db/backends/sqlite3/base.py", line 413, in execute
    return Database.Cursor.execute(self, query, params)
sqlite3.OperationalError: attempt to write a readonly database

The above exception was the direct cause of the following exception:

Traceback (most recent call last):
  File "/home/venv/lib/python3.6/site-packages/django/core/handlers/exception.py", line 47, in inner
    response = get_response(request)
  File "/home/venv/lib/python3.6/site-packages/django/utils/deprecation.py", line 116, in __call__
    response = self.process_response(request, response)
  File "/home/venv/lib/python3.6/site-packages/django/contrib/sessions/middleware.py", line 63, in process_response
    request.session.save()
  File "/home/venv/lib/python3.6/site-packages/django/contrib/sessions/backends/db.py", line 81, in save
    return self.create()
  File "/home/venv/lib/python3.6/site-packages/django/contrib/sessions/backends/db.py", line 55, in create
    self.save(must_create=True)
  File "/home/venv/lib/python3.6/site-packages/django/contrib/sessions/backends/db.py", line 87, in save
    obj.save(force_insert=must_create, force_update=not must_create, using=using)
  File "/home/venv/lib/python3.6/site-packages/django/db/models/base.py", line 754, in save
    force_update=force_update, update_fields=update_fields)
  File "/home/venv/lib/python3.6/site-packages/django/db/models/base.py", line 792, in save_base
    force_update, using, update_fields,
  File "/home/venv/lib/python3.6/site-packages/django/db/models/base.py", line 895, in _save_table
    results = self._do_insert(cls._base_manager, using, fields, returning_fields, raw)
  File "/home/venv/lib/python3.6/site-packages/django/db/models/base.py", line 935, in _do_insert
    using=using, raw=raw,
  File "/home/venv/lib/python3.6/site-packages/django/db/models/manager.py", line 85, in manager_method
    return getattr(self.get_queryset(), name)(*args, **kwargs)
  File "/home/venv/lib/python3.6/site-packages/django/db/models/query.py", line 1249, in _insert
    return query.get_compiler(using=using).execute_sql(returning_fields)
  File "/home/venv/lib/python3.6/site-packages/django/db/models/sql/compiler.py", line 1397, in execute_sql
    cursor.execute(sql, params)
  File "/home/venv/lib/python3.6/site-packages/django/db/backends/utils.py", line 98, in execute
    return super().execute(sql, params)
  File "/home/venv/lib/python3.6/site-packages/django/db/backends/utils.py", line 66, in execute
    return self._execute_with_wrappers(sql, params, many=False, executor=self._execute)
  File "/home/venv/lib/python3.6/site-packages/django/db/backends/utils.py", line 75, in _execute_with_wrappers
    return executor(sql, params, many, context)
  File "/home/venv/lib/python3.6/site-packages/django/db/backends/utils.py", line 84, in _execute
    return self.cursor.execute(sql, params)
  File "/home/venv/lib/python3.6/site-packages/django/db/utils.py", line 90, in __exit__
    raise dj_exc_value.with_traceback(traceback) from exc_value
  File "/home/venv/lib/python3.6/site-packages/django/db/backends/utils.py", line 84, in _execute
    return self.cursor.execute(sql, params)
  File "/home/venv/lib/python3.6/site-packages/django/db/backends/sqlite3/base.py", line 413, in execute
    return Database.Cursor.execute(self, query, params)
django.db.utils.OperationalError: attempt to write a readonly database
Internal Server Error: /
Traceback (most recent call last):
  File "/home/venv/lib/python3.6/site-packages/django/db/backends/utils.py", line 84, in _execute
    return self.cursor.execute(sql, params)
  File "/home/venv/lib/python3.6/site-packages/django/db/backends/sqlite3/base.py", line 413, in execute
    return Database.Cursor.execute(self, query, params)
sqlite3.OperationalError: attempt to write a readonly database

The above exception was the direct cause of the following exception:

Traceback (most recent call last):
  File "/home/venv/lib/python3.6/site-packages/django/core/handlers/exception.py", line 47, in inner
    response = get_response(request)
  File "/home/venv/lib/python3.6/site-packages/django/utils/deprecation.py", line 116, in __call__
    response = self.process_response(request, response)
  File "/home/venv/lib/python3.6/site-packages/django/contrib/sessions/middleware.py", line 63, in process_response
    request.session.save()
  File "/home/venv/lib/python3.6/site-packages/django/contrib/sessions/backends/db.py", line 81, in save
    return self.create()
  File "/home/venv/lib/python3.6/site-packages/django/contrib/sessions/backends/db.py", line 55, in create
    self.save(must_create=True)
  File "/home/venv/lib/python3.6/site-packages/django/contrib/sessions/backends/db.py", line 87, in save
    obj.save(force_insert=must_create, force_update=not must_create, using=using)
  File "/home/venv/lib/python3.6/site-packages/django/db/models/base.py", line 754, in save
    force_update=force_update, update_fields=update_fields)
  File "/home/venv/lib/python3.6/site-packages/django/db/models/base.py", line 792, in save_base
    force_update, using, update_fields,
  File "/home/venv/lib/python3.6/site-packages/django/db/models/base.py", line 895, in _save_table
    results = self._do_insert(cls._base_manager, using, fields, returning_fields, raw)
  File "/home/venv/lib/python3.6/site-packages/django/db/models/base.py", line 935, in _do_insert
    using=using, raw=raw,
  File "/home/venv/lib/python3.6/site-packages/django/db/models/manager.py", line 85, in manager_method
    return getattr(self.get_queryset(), name)(*args, **kwargs)
  File "/home/venv/lib/python3.6/site-packages/django/db/models/query.py", line 1249, in _insert
    return query.get_compiler(using=using).execute_sql(returning_fields)
  File "/home/venv/lib/python3.6/site-packages/django/db/models/sql/compiler.py", line 1397, in execute_sql
    cursor.execute(sql, params)
  File "/home/venv/lib/python3.6/site-packages/django/db/backends/utils.py", line 98, in execute
    return super().execute(sql, params)
  File "/home/venv/lib/python3.6/site-packages/django/db/backends/utils.py", line 66, in execute
    return self._execute_with_wrappers(sql, params, many=False, executor=self._execute)
  File "/home/venv/lib/python3.6/site-packages/django/db/backends/utils.py", line 75, in _execute_with_wrappers
    return executor(sql, params, many, context)
  File "/home/venv/lib/python3.6/site-packages/django/db/backends/utils.py", line 84, in _execute
    return self.cursor.execute(sql, params)
  File "/home/venv/lib/python3.6/site-packages/django/db/utils.py", line 90, in __exit__
    raise dj_exc_value.with_traceback(traceback) from exc_value
  File "/home/venv/lib/python3.6/site-packages/django/db/backends/utils.py", line 84, in _execute
    return self.cursor.execute(sql, params)
  File "/home/venv/lib/python3.6/site-packages/django/db/backends/sqlite3/base.py", line 413, in execute
    return Database.Cursor.execute(self, query, params)
django.db.utils.OperationalError: attempt to write a readonly database
Internal Server Error: /
Traceback (most recent call last):
  File "/home/venv/lib/python3.6/site-packages/django/db/backends/utils.py", line 84, in _execute
    return self.cursor.execute(sql, params)
  File "/home/venv/lib/python3.6/site-packages/django/db/backends/sqlite3/base.py", line 413, in execute
    return Database.Cursor.execute(self, query, params)
sqlite3.OperationalError: attempt to write a readonly database

The above exception was the direct cause of the following exception:

Traceback (most recent call last):
  File "/home/venv/lib/python3.6/site-packages/django/core/handlers/exception.py", line 47, in inner
    response = get_response(request)
  File "/home/venv/lib/python3.6/site-packages/django/utils/deprecation.py", line 116, in __call__
    response = self.process_response(request, response)
  File "/home/venv/lib/python3.6/site-packages/django/contrib/sessions/middleware.py", line 63, in process_response
    request.session.save()
  File "/home/venv/lib/python3.6/site-packages/django/contrib/sessions/backends/db.py", line 81, in save
    return self.create()
  File "/home/venv/lib/python3.6/site-packages/django/contrib/sessions/backends/db.py", line 55, in create
    self.save(must_create=True)
  File "/home/venv/lib/python3.6/site-packages/django/contrib/sessions/backends/db.py", line 87, in save
    obj.save(force_insert=must_create, force_update=not must_create, using=using)
  File "/home/venv/lib/python3.6/site-packages/django/db/models/base.py", line 754, in save
    force_update=force_update, update_fields=update_fields)
  File "/home/venv/lib/python3.6/site-packages/django/db/models/base.py", line 792, in save_base
    force_update, using, update_fields,
  File "/home/venv/lib/python3.6/site-packages/django/db/models/base.py", line 895, in _save_table
    results = self._do_insert(cls._base_manager, using, fields, returning_fields, raw)
  File "/home/venv/lib/python3.6/site-packages/django/db/models/base.py", line 935, in _do_insert
    using=using, raw=raw,
  File "/home/venv/lib/python3.6/site-packages/django/db/models/manager.py", line 85, in manager_method
    return getattr(self.get_queryset(), name)(*args, **kwargs)
  File "/home/venv/lib/python3.6/site-packages/django/db/models/query.py", line 1249, in _insert
    return query.get_compiler(using=using).execute_sql(returning_fields)
  File "/home/venv/lib/python3.6/site-packages/django/db/models/sql/compiler.py", line 1397, in execute_sql
    cursor.execute(sql, params)
  File "/home/venv/lib/python3.6/site-packages/django/db/backends/utils.py", line 98, in execute
    return super().execute(sql, params)
  File "/home/venv/lib/python3.6/site-packages/django/db/backends/utils.py", line 66, in execute
    return self._execute_with_wrappers(sql, params, many=False, executor=self._execute)
  File "/home/venv/lib/python3.6/site-packages/django/db/backends/utils.py", line 75, in _execute_with_wrappers
    return executor(sql, params, many, context)
  File "/home/venv/lib/python3.6/site-packages/django/db/backends/utils.py", line 84, in _execute
    return self.cursor.execute(sql, params)
  File "/home/venv/lib/python3.6/site-packages/django/db/utils.py", line 90, in __exit__
    raise dj_exc_value.with_traceback(traceback) from exc_value
  File "/home/venv/lib/python3.6/site-packages/django/db/backends/utils.py", line 84, in _execute
    return self.cursor.execute(sql, params)
  File "/home/venv/lib/python3.6/site-packages/django/db/backends/sqlite3/base.py", line 413, in execute
    return Database.Cursor.execute(self, query, params)
django.db.utils.OperationalError: attempt to write a readonly database
Internal Server Error: /
Traceback (most recent call last):
  File "/home/venv/lib/python3.6/site-packages/django/db/backends/utils.py", line 84, in _execute
    return self.cursor.execute(sql, params)
  File "/home/venv/lib/python3.6/site-packages/django/db/backends/sqlite3/base.py", line 413, in execute
    return Database.Cursor.execute(self, query, params)
sqlite3.OperationalError: attempt to write a readonly database

The above exception was the direct cause of the following exception:

Traceback (most recent call last):
  File "/home/venv/lib/python3.6/site-packages/django/core/handlers/exception.py", line 47, in inner
    response = get_response(request)
  File "/home/venv/lib/python3.6/site-packages/django/utils/deprecation.py", line 116, in __call__
    response = self.process_response(request, response)
  File "/home/venv/lib/python3.6/site-packages/django/contrib/sessions/middleware.py", line 63, in process_response
    request.session.save()
  File "/home/venv/lib/python3.6/site-packages/django/contrib/sessions/backends/db.py", line 81, in save
    return self.create()
  File "/home/venv/lib/python3.6/site-packages/django/contrib/sessions/backends/db.py", line 55, in create
    self.save(must_create=True)
  File "/home/venv/lib/python3.6/site-packages/django/contrib/sessions/backends/db.py", line 87, in save
    obj.save(force_insert=must_create, force_update=not must_create, using=using)
  File "/home/venv/lib/python3.6/site-packages/django/db/models/base.py", line 754, in save
    force_update=force_update, update_fields=update_fields)
  File "/home/venv/lib/python3.6/site-packages/django/db/models/base.py", line 792, in save_base
    force_update, using, update_fields,
  File "/home/venv/lib/python3.6/site-packages/django/db/models/base.py", line 895, in _save_table
    results = self._do_insert(cls._base_manager, using, fields, returning_fields, raw)
  File "/home/venv/lib/python3.6/site-packages/django/db/models/base.py", line 935, in _do_insert
    using=using, raw=raw,
  File "/home/venv/lib/python3.6/site-packages/django/db/models/manager.py", line 85, in manager_method
    return getattr(self.get_queryset(), name)(*args, **kwargs)
  File "/home/venv/lib/python3.6/site-packages/django/db/models/query.py", line 1249, in _insert
    return query.get_compiler(using=using).execute_sql(returning_fields)
  File "/home/venv/lib/python3.6/site-packages/django/db/models/sql/compiler.py", line 1397, in execute_sql
    cursor.execute(sql, params)
  File "/home/venv/lib/python3.6/site-packages/django/db/backends/utils.py", line 98, in execute
    return super().execute(sql, params)
  File "/home/venv/lib/python3.6/site-packages/django/db/backends/utils.py", line 66, in execute
    return self._execute_with_wrappers(sql, params, many=False, executor=self._execute)
  File "/home/venv/lib/python3.6/site-packages/django/db/backends/utils.py", line 75, in _execute_with_wrappers
    return executor(sql, params, many, context)
  File "/home/venv/lib/python3.6/site-packages/django/db/backends/utils.py", line 84, in _execute
    return self.cursor.execute(sql, params)
  File "/home/venv/lib/python3.6/site-packages/django/db/utils.py", line 90, in __exit__
    raise dj_exc_value.with_traceback(traceback) from exc_value
  File "/home/venv/lib/python3.6/site-packages/django/db/backends/utils.py", line 84, in _execute
    return self.cursor.execute(sql, params)
  File "/home/venv/lib/python3.6/site-packages/django/db/backends/sqlite3/base.py", line 413, in execute
    return Database.Cursor.execute(self, query, params)
django.db.utils.OperationalError: attempt to write a readonly database
Internal Server Error: /
Traceback (most recent call last):
  File "/home/venv/lib/python3.6/site-packages/django/db/backends/utils.py", line 84, in _execute
    return self.cursor.execute(sql, params)
  File "/home/venv/lib/python3.6/site-packages/django/db/backends/sqlite3/base.py", line 413, in execute
    return Database.Cursor.execute(self, query, params)
sqlite3.OperationalError: attempt to write a readonly database

The above exception was the direct cause of the following exception:

Traceback (most recent call last):
  File "/home/venv/lib/python3.6/site-packages/django/core/handlers/exception.py", line 47, in inner
    response = get_response(request)
  File "/home/venv/lib/python3.6/site-packages/django/utils/deprecation.py", line 116, in __call__
    response = self.process_response(request, response)
  File "/home/venv/lib/python3.6/site-packages/django/contrib/sessions/middleware.py", line 63, in process_response
    request.session.save()
  File "/home/venv/lib/python3.6/site-packages/django/contrib/sessions/backends/db.py", line 81, in save
    return self.create()
  File "/home/venv/lib/python3.6/site-packages/django/contrib/sessions/backends/db.py", line 55, in create
    self.save(must_create=True)
  File "/home/venv/lib/python3.6/site-packages/django/contrib/sessions/backends/db.py", line 87, in save
    obj.save(force_insert=must_create, force_update=not must_create, using=using)
  File "/home/venv/lib/python3.6/site-packages/django/db/models/base.py", line 754, in save
    force_update=force_update, update_fields=update_fields)
  File "/home/venv/lib/python3.6/site-packages/django/db/models/base.py", line 792, in save_base
    force_update, using, update_fields,
  File "/home/venv/lib/python3.6/site-packages/django/db/models/base.py", line 895, in _save_table
    results = self._do_insert(cls._base_manager, using, fields, returning_fields, raw)
  File "/home/venv/lib/python3.6/site-packages/django/db/models/base.py", line 935, in _do_insert
    using=using, raw=raw,
  File "/home/venv/lib/python3.6/site-packages/django/db/models/manager.py", line 85, in manager_method
    return getattr(self.get_queryset(), name)(*args, **kwargs)
  File "/home/venv/lib/python3.6/site-packages/django/db/models/query.py", line 1249, in _insert
    return query.get_compiler(using=using).execute_sql(returning_fields)
  File "/home/venv/lib/python3.6/site-packages/django/db/models/sql/compiler.py", line 1397, in execute_sql
    cursor.execute(sql, params)
  File "/home/venv/lib/python3.6/site-packages/django/db/backends/utils.py", line 98, in execute
    return super().execute(sql, params)
  File "/home/venv/lib/python3.6/site-packages/django/db/backends/utils.py", line 66, in execute
    return self._execute_with_wrappers(sql, params, many=False, executor=self._execute)
  File "/home/venv/lib/python3.6/site-packages/django/db/backends/utils.py", line 75, in _execute_with_wrappers
    return executor(sql, params, many, context)
  File "/home/venv/lib/python3.6/site-packages/django/db/backends/utils.py", line 84, in _execute
    return self.cursor.execute(sql, params)
  File "/home/venv/lib/python3.6/site-packages/django/db/utils.py", line 90, in __exit__
    raise dj_exc_value.with_traceback(traceback) from exc_value
  File "/home/venv/lib/python3.6/site-packages/django/db/backends/utils.py", line 84, in _execute
    return self.cursor.execute(sql, params)
  File "/home/venv/lib/python3.6/site-packages/django/db/backends/sqlite3/base.py", line 413, in execute
    return Database.Cursor.execute(self, query, params)
django.db.utils.OperationalError: attempt to write a readonly database
Internal Server Error: /
Traceback (most recent call last):
  File "/home/venv/lib/python3.6/site-packages/django/db/backends/utils.py", line 84, in _execute
    return self.cursor.execute(sql, params)
  File "/home/venv/lib/python3.6/site-packages/django/db/backends/sqlite3/base.py", line 413, in execute
    return Database.Cursor.execute(self, query, params)
sqlite3.OperationalError: attempt to write a readonly database

The above exception was the direct cause of the following exception:

Traceback (most recent call last):
  File "/home/venv/lib/python3.6/site-packages/django/core/handlers/exception.py", line 47, in inner
    response = get_response(request)
  File "/home/venv/lib/python3.6/site-packages/django/utils/deprecation.py", line 116, in __call__
    response = self.process_response(request, response)
  File "/home/venv/lib/python3.6/site-packages/django/contrib/sessions/middleware.py", line 63, in process_response
    request.session.save()
  File "/home/venv/lib/python3.6/site-packages/django/contrib/sessions/backends/db.py", line 81, in save
    return self.create()
  File "/home/venv/lib/python3.6/site-packages/django/contrib/sessions/backends/db.py", line 55, in create
    self.save(must_create=True)
  File "/home/venv/lib/python3.6/site-packages/django/contrib/sessions/backends/db.py", line 87, in save
    obj.save(force_insert=must_create, force_update=not must_create, using=using)
  File "/home/venv/lib/python3.6/site-packages/django/db/models/base.py", line 754, in save
    force_update=force_update, update_fields=update_fields)
  File "/home/venv/lib/python3.6/site-packages/django/db/models/base.py", line 792, in save_base
    force_update, using, update_fields,
  File "/home/venv/lib/python3.6/site-packages/django/db/models/base.py", line 895, in _save_table
    results = self._do_insert(cls._base_manager, using, fields, returning_fields, raw)
  File "/home/venv/lib/python3.6/site-packages/django/db/models/base.py", line 935, in _do_insert
    using=using, raw=raw,
  File "/home/venv/lib/python3.6/site-packages/django/db/models/manager.py", line 85, in manager_method
    return getattr(self.get_queryset(), name)(*args, **kwargs)
  File "/home/venv/lib/python3.6/site-packages/django/db/models/query.py", line 1249, in _insert
    return query.get_compiler(using=using).execute_sql(returning_fields)
  File "/home/venv/lib/python3.6/site-packages/django/db/models/sql/compiler.py", line 1397, in execute_sql
    cursor.execute(sql, params)
  File "/home/venv/lib/python3.6/site-packages/django/db/backends/utils.py", line 98, in execute
    return super().execute(sql, params)
  File "/home/venv/lib/python3.6/site-packages/django/db/backends/utils.py", line 66, in execute
    return self._execute_with_wrappers(sql, params, many=False, executor=self._execute)
  File "/home/venv/lib/python3.6/site-packages/django/db/backends/utils.py", line 75, in _execute_with_wrappers
    return executor(sql, params, many, context)
  File "/home/venv/lib/python3.6/site-packages/django/db/backends/utils.py", line 84, in _execute
    return self.cursor.execute(sql, params)
  File "/home/venv/lib/python3.6/site-packages/django/db/utils.py", line 90, in __exit__
    raise dj_exc_value.with_traceback(traceback) from exc_value
  File "/home/venv/lib/python3.6/site-packages/django/db/backends/utils.py", line 84, in _execute
    return self.cursor.execute(sql, params)
  File "/home/venv/lib/python3.6/site-packages/django/db/backends/sqlite3/base.py", line 413, in execute
    return Database.Cursor.execute(self, query, params)
django.db.utils.OperationalError: attempt to write a readonly database
Internal Server Error: /
Traceback (most recent call last):
  File "/home/venv/lib/python3.6/site-packages/django/db/backends/utils.py", line 84, in _execute
    return self.cursor.execute(sql, params)
  File "/home/venv/lib/python3.6/site-packages/django/db/backends/sqlite3/base.py", line 413, in execute
    return Database.Cursor.execute(self, query, params)
sqlite3.OperationalError: attempt to write a readonly database

The above exception was the direct cause of the following exception:

Traceback (most recent call last):
  File "/home/venv/lib/python3.6/site-packages/django/core/handlers/exception.py", line 47, in inner
    response = get_response(request)
  File "/home/venv/lib/python3.6/site-packages/django/utils/deprecation.py", line 116, in __call__
    response = self.process_response(request, response)
  File "/home/venv/lib/python3.6/site-packages/django/contrib/sessions/middleware.py", line 63, in process_response
    request.session.save()
  File "/home/venv/lib/python3.6/site-packages/django/contrib/sessions/backends/db.py", line 81, in save
    return self.create()
  File "/home/venv/lib/python3.6/site-packages/django/contrib/sessions/backends/db.py", line 55, in create
    self.save(must_create=True)
  File "/home/venv/lib/python3.6/site-packages/django/contrib/sessions/backends/db.py", line 87, in save
    obj.save(force_insert=must_create, force_update=not must_create, using=using)
  File "/home/venv/lib/python3.6/site-packages/django/db/models/base.py", line 754, in save
    force_update=force_update, update_fields=update_fields)
  File "/home/venv/lib/python3.6/site-packages/django/db/models/base.py", line 792, in save_base
    force_update, using, update_fields,
  File "/home/venv/lib/python3.6/site-packages/django/db/models/base.py", line 895, in _save_table
    results = self._do_insert(cls._base_manager, using, fields, returning_fields, raw)
  File "/home/venv/lib/python3.6/site-packages/django/db/models/base.py", line 935, in _do_insert
    using=using, raw=raw,
  File "/home/venv/lib/python3.6/site-packages/django/db/models/manager.py", line 85, in manager_method
    return getattr(self.get_queryset(), name)(*args, **kwargs)
  File "/home/venv/lib/python3.6/site-packages/django/db/models/query.py", line 1249, in _insert
    return query.get_compiler(using=using).execute_sql(returning_fields)
  File "/home/venv/lib/python3.6/site-packages/django/db/models/sql/compiler.py", line 1397, in execute_sql
    cursor.execute(sql, params)
  File "/home/venv/lib/python3.6/site-packages/django/db/backends/utils.py", line 98, in execute
    return super().execute(sql, params)
  File "/home/venv/lib/python3.6/site-packages/django/db/backends/utils.py", line 66, in execute
    return self._execute_with_wrappers(sql, params, many=False, executor=self._execute)
  File "/home/venv/lib/python3.6/site-packages/django/db/backends/utils.py", line 75, in _execute_with_wrappers
    return executor(sql, params, many, context)
  File "/home/venv/lib/python3.6/site-packages/django/db/backends/utils.py", line 84, in _execute
    return self.cursor.execute(sql, params)
  File "/home/venv/lib/python3.6/site-packages/django/db/utils.py", line 90, in __exit__
    raise dj_exc_value.with_traceback(traceback) from exc_value
  File "/home/venv/lib/python3.6/site-packages/django/db/backends/utils.py", line 84, in _execute
    return self.cursor.execute(sql, params)
  File "/home/venv/lib/python3.6/site-packages/django/db/backends/sqlite3/base.py", line 413, in execute
    return Database.Cursor.execute(self, query, params)
django.db.utils.OperationalError: attempt to write a readonly database
Internal Server Error: /
Traceback (most recent call last):
  File "/home/venv/lib/python3.6/site-packages/django/db/backends/utils.py", line 84, in _execute
    return self.cursor.execute(sql, params)
  File "/home/venv/lib/python3.6/site-packages/django/db/backends/sqlite3/base.py", line 413, in execute
    return Database.Cursor.execute(self, query, params)
sqlite3.OperationalError: attempt to write a readonly database

The above exception was the direct cause of the following exception:

Traceback (most recent call last):
  File "/home/venv/lib/python3.6/site-packages/django/core/handlers/exception.py", line 47, in inner
    response = get_response(request)
  File "/home/venv/lib/python3.6/site-packages/django/utils/deprecation.py", line 116, in __call__
    response = self.process_response(request, response)
  File "/home/venv/lib/python3.6/site-packages/django/contrib/sessions/middleware.py", line 63, in process_response
    request.session.save()
  File "/home/venv/lib/python3.6/site-packages/django/contrib/sessions/backends/db.py", line 81, in save
    return self.create()
  File "/home/venv/lib/python3.6/site-packages/django/contrib/sessions/backends/db.py", line 55, in create
    self.save(must_create=True)
  File "/home/venv/lib/python3.6/site-packages/django/contrib/sessions/backends/db.py", line 87, in save
    obj.save(force_insert=must_create, force_update=not must_create, using=using)
  File "/home/venv/lib/python3.6/site-packages/django/db/models/base.py", line 754, in save
    force_update=force_update, update_fields=update_fields)
  File "/home/venv/lib/python3.6/site-packages/django/db/models/base.py", line 792, in save_base
    force_update, using, update_fields,
  File "/home/venv/lib/python3.6/site-packages/django/db/models/base.py", line 895, in _save_table
    results = self._do_insert(cls._base_manager, using, fields, returning_fields, raw)
  File "/home/venv/lib/python3.6/site-packages/django/db/models/base.py", line 935, in _do_insert
    using=using, raw=raw,
  File "/home/venv/lib/python3.6/site-packages/django/db/models/manager.py", line 85, in manager_method
    return getattr(self.get_queryset(), name)(*args, **kwargs)
  File "/home/venv/lib/python3.6/site-packages/django/db/models/query.py", line 1249, in _insert
    return query.get_compiler(using=using).execute_sql(returning_fields)
  File "/home/venv/lib/python3.6/site-packages/django/db/models/sql/compiler.py", line 1397, in execute_sql
    cursor.execute(sql, params)
  File "/home/venv/lib/python3.6/site-packages/django/db/backends/utils.py", line 98, in execute
    return super().execute(sql, params)
  File "/home/venv/lib/python3.6/site-packages/django/db/backends/utils.py", line 66, in execute
    return self._execute_with_wrappers(sql, params, many=False, executor=self._execute)
  File "/home/venv/lib/python3.6/site-packages/django/db/backends/utils.py", line 75, in _execute_with_wrappers
    return executor(sql, params, many, context)
  File "/home/venv/lib/python3.6/site-packages/django/db/backends/utils.py", line 84, in _execute
    return self.cursor.execute(sql, params)
  File "/home/venv/lib/python3.6/site-packages/django/db/utils.py", line 90, in __exit__
    raise dj_exc_value.with_traceback(traceback) from exc_value
  File "/home/venv/lib/python3.6/site-packages/django/db/backends/utils.py", line 84, in _execute
    return self.cursor.execute(sql, params)
  File "/home/venv/lib/python3.6/site-packages/django/db/backends/sqlite3/base.py", line 413, in execute
    return Database.Cursor.execute(self, query, params)
django.db.utils.OperationalError: attempt to write a readonly database
Not Found: /favicon.ico
Internal Server Error: /
Traceback (most recent call last):
  File "/home/venv/lib/python3.6/site-packages/django/db/backends/utils.py", line 84, in _execute
    return self.cursor.execute(sql, params)
  File "/home/venv/lib/python3.6/site-packages/django/db/backends/sqlite3/base.py", line 413, in execute
    return Database.Cursor.execute(self, query, params)
sqlite3.OperationalError: attempt to write a readonly database

The above exception was the direct cause of the following exception:

Traceback (most recent call last):
  File "/home/venv/lib/python3.6/site-packages/django/core/handlers/exception.py", line 47, in inner
    response = get_response(request)
  File "/home/venv/lib/python3.6/site-packages/django/utils/deprecation.py", line 116, in __call__
    response = self.process_response(request, response)
  File "/home/venv/lib/python3.6/site-packages/django/contrib/sessions/middleware.py", line 63, in process_response
    request.session.save()
  File "/home/venv/lib/python3.6/site-packages/django/contrib/sessions/backends/db.py", line 81, in save
    return self.create()
  File "/home/venv/lib/python3.6/site-packages/django/contrib/sessions/backends/db.py", line 55, in create
    self.save(must_create=True)
  File "/home/venv/lib/python3.6/site-packages/django/contrib/sessions/backends/db.py", line 87, in save
    obj.save(force_insert=must_create, force_update=not must_create, using=using)
  File "/home/venv/lib/python3.6/site-packages/django/db/models/base.py", line 754, in save
    force_update=force_update, update_fields=update_fields)
  File "/home/venv/lib/python3.6/site-packages/django/db/models/base.py", line 792, in save_base
    force_update, using, update_fields,
  File "/home/venv/lib/python3.6/site-packages/django/db/models/base.py", line 895, in _save_table
    results = self._do_insert(cls._base_manager, using, fields, returning_fields, raw)
  File "/home/venv/lib/python3.6/site-packages/django/db/models/base.py", line 935, in _do_insert
    using=using, raw=raw,
  File "/home/venv/lib/python3.6/site-packages/django/db/models/manager.py", line 85, in manager_method
    return getattr(self.get_queryset(), name)(*args, **kwargs)
  File "/home/venv/lib/python3.6/site-packages/django/db/models/query.py", line 1249, in _insert
    return query.get_compiler(using=using).execute_sql(returning_fields)
  File "/home/venv/lib/python3.6/site-packages/django/db/models/sql/compiler.py", line 1397, in execute_sql
    cursor.execute(sql, params)
  File "/home/venv/lib/python3.6/site-packages/django/db/backends/utils.py", line 98, in execute
    return super().execute(sql, params)
  File "/home/venv/lib/python3.6/site-packages/django/db/backends/utils.py", line 66, in execute
    return self._execute_with_wrappers(sql, params, many=False, executor=self._execute)
  File "/home/venv/lib/python3.6/site-packages/django/db/backends/utils.py", line 75, in _execute_with_wrappers
    return executor(sql, params, many, context)
  File "/home/venv/lib/python3.6/site-packages/django/db/backends/utils.py", line 84, in _execute
    return self.cursor.execute(sql, params)
  File "/home/venv/lib/python3.6/site-packages/django/db/utils.py", line 90, in __exit__
    raise dj_exc_value.with_traceback(traceback) from exc_value
  File "/home/venv/lib/python3.6/site-packages/django/db/backends/utils.py", line 84, in _execute
    return self.cursor.execute(sql, params)
  File "/home/venv/lib/python3.6/site-packages/django/db/backends/sqlite3/base.py", line 413, in execute
    return Database.Cursor.execute(self, query, params)
django.db.utils.OperationalError: attempt to write a readonly database
Not Found: /favicon.ico
Internal Server Error: /
Traceback (most recent call last):
  File "/home/venv/lib/python3.6/site-packages/django/db/backends/utils.py", line 84, in _execute
    return self.cursor.execute(sql, params)
  File "/home/venv/lib/python3.6/site-packages/django/db/backends/sqlite3/base.py", line 413, in execute
    return Database.Cursor.execute(self, query, params)
sqlite3.OperationalError: attempt to write a readonly database

The above exception was the direct cause of the following exception:

Traceback (most recent call last):
  File "/home/venv/lib/python3.6/site-packages/django/core/handlers/exception.py", line 47, in inner
    response = get_response(request)
  File "/home/venv/lib/python3.6/site-packages/django/utils/deprecation.py", line 116, in __call__
    response = self.process_response(request, response)
  File "/home/venv/lib/python3.6/site-packages/django/contrib/sessions/middleware.py", line 63, in process_response
    request.session.save()
  File "/home/venv/lib/python3.6/site-packages/django/contrib/sessions/backends/db.py", line 81, in save
    return self.create()
  File "/home/venv/lib/python3.6/site-packages/django/contrib/sessions/backends/db.py", line 55, in create
    self.save(must_create=True)
  File "/home/venv/lib/python3.6/site-packages/django/contrib/sessions/backends/db.py", line 87, in save
    obj.save(force_insert=must_create, force_update=not must_create, using=using)
  File "/home/venv/lib/python3.6/site-packages/django/db/models/base.py", line 754, in save
    force_update=force_update, update_fields=update_fields)
  File "/home/venv/lib/python3.6/site-packages/django/db/models/base.py", line 792, in save_base
    force_update, using, update_fields,
  File "/home/venv/lib/python3.6/site-packages/django/db/models/base.py", line 895, in _save_table
    results = self._do_insert(cls._base_manager, using, fields, returning_fields, raw)
  File "/home/venv/lib/python3.6/site-packages/django/db/models/base.py", line 935, in _do_insert
    using=using, raw=raw,
  File "/home/venv/lib/python3.6/site-packages/django/db/models/manager.py", line 85, in manager_method
    return getattr(self.get_queryset(), name)(*args, **kwargs)
  File "/home/venv/lib/python3.6/site-packages/django/db/models/query.py", line 1249, in _insert
    return query.get_compiler(using=using).execute_sql(returning_fields)
  File "/home/venv/lib/python3.6/site-packages/django/db/models/sql/compiler.py", line 1397, in execute_sql
    cursor.execute(sql, params)
  File "/home/venv/lib/python3.6/site-packages/django/db/backends/utils.py", line 98, in execute
    return super().execute(sql, params)
  File "/home/venv/lib/python3.6/site-packages/django/db/backends/utils.py", line 66, in execute
    return self._execute_with_wrappers(sql, params, many=False, executor=self._execute)
  File "/home/venv/lib/python3.6/site-packages/django/db/backends/utils.py", line 75, in _execute_with_wrappers
    return executor(sql, params, many, context)
  File "/home/venv/lib/python3.6/site-packages/django/db/backends/utils.py", line 84, in _execute
    return self.cursor.execute(sql, params)
  File "/home/venv/lib/python3.6/site-packages/django/db/utils.py", line 90, in __exit__
    raise dj_exc_value.with_traceback(traceback) from exc_value
  File "/home/venv/lib/python3.6/site-packages/django/db/backends/utils.py", line 84, in _execute
    return self.cursor.execute(sql, params)
  File "/home/venv/lib/python3.6/site-packages/django/db/backends/sqlite3/base.py", line 413, in execute
    return Database.Cursor.execute(self, query, params)
django.db.utils.OperationalError: attempt to write a readonly database
Internal Server Error: /
Traceback (most recent call last):
  File "/home/venv/lib/python3.6/site-packages/django/db/backends/utils.py", line 84, in _execute
    return self.cursor.execute(sql, params)
  File "/home/venv/lib/python3.6/site-packages/django/db/backends/sqlite3/base.py", line 413, in execute
    return Database.Cursor.execute(self, query, params)
sqlite3.OperationalError: attempt to write a readonly database

The above exception was the direct cause of the following exception:

Traceback (most recent call last):
  File "/home/venv/lib/python3.6/site-packages/django/core/handlers/exception.py", line 47, in inner
    response = get_response(request)
  File "/home/venv/lib/python3.6/site-packages/django/utils/deprecation.py", line 116, in __call__
    response = self.process_response(request, response)
  File "/home/venv/lib/python3.6/site-packages/django/contrib/sessions/middleware.py", line 63, in process_response
    request.session.save()
  File "/home/venv/lib/python3.6/site-packages/django/contrib/sessions/backends/db.py", line 81, in save
    return self.create()
  File "/home/venv/lib/python3.6/site-packages/django/contrib/sessions/backends/db.py", line 55, in create
    self.save(must_create=True)
  File "/home/venv/lib/python3.6/site-packages/django/contrib/sessions/backends/db.py", line 87, in save
    obj.save(force_insert=must_create, force_update=not must_create, using=using)
  File "/home/venv/lib/python3.6/site-packages/django/db/models/base.py", line 754, in save
    force_update=force_update, update_fields=update_fields)
  File "/home/venv/lib/python3.6/site-packages/django/db/models/base.py", line 792, in save_base
    force_update, using, update_fields,
  File "/home/venv/lib/python3.6/site-packages/django/db/models/base.py", line 895, in _save_table
    results = self._do_insert(cls._base_manager, using, fields, returning_fields, raw)
  File "/home/venv/lib/python3.6/site-packages/django/db/models/base.py", line 935, in _do_insert
    using=using, raw=raw,
  File "/home/venv/lib/python3.6/site-packages/django/db/models/manager.py", line 85, in manager_method
    return getattr(self.get_queryset(), name)(*args, **kwargs)
  File "/home/venv/lib/python3.6/site-packages/django/db/models/query.py", line 1249, in _insert
    return query.get_compiler(using=using).execute_sql(returning_fields)
  File "/home/venv/lib/python3.6/site-packages/django/db/models/sql/compiler.py", line 1397, in execute_sql
    cursor.execute(sql, params)
  File "/home/venv/lib/python3.6/site-packages/django/db/backends/utils.py", line 98, in execute
    return super().execute(sql, params)
  File "/home/venv/lib/python3.6/site-packages/django/db/backends/utils.py", line 66, in execute
    return self._execute_with_wrappers(sql, params, many=False, executor=self._execute)
  File "/home/venv/lib/python3.6/site-packages/django/db/backends/utils.py", line 75, in _execute_with_wrappers
    return executor(sql, params, many, context)
  File "/home/venv/lib/python3.6/site-packages/django/db/backends/utils.py", line 84, in _execute
    return self.cursor.execute(sql, params)
  File "/home/venv/lib/python3.6/site-packages/django/db/utils.py", line 90, in __exit__
    raise dj_exc_value.with_traceback(traceback) from exc_value
  File "/home/venv/lib/python3.6/site-packages/django/db/backends/utils.py", line 84, in _execute
    return self.cursor.execute(sql, params)
  File "/home/venv/lib/python3.6/site-packages/django/db/backends/sqlite3/base.py", line 413, in execute
    return Database.Cursor.execute(self, query, params)
django.db.utils.OperationalError: attempt to write a readonly database
Internal Server Error: /
Traceback (most recent call last):
  File "/home/venv/lib/python3.6/site-packages/django/db/backends/utils.py", line 84, in _execute
    return self.cursor.execute(sql, params)
  File "/home/venv/lib/python3.6/site-packages/django/db/backends/sqlite3/base.py", line 413, in execute
    return Database.Cursor.execute(self, query, params)
sqlite3.OperationalError: attempt to write a readonly database

The above exception was the direct cause of the following exception:

Traceback (most recent call last):
  File "/home/venv/lib/python3.6/site-packages/django/core/handlers/exception.py", line 47, in inner
    response = get_response(request)
  File "/home/venv/lib/python3.6/site-packages/django/utils/deprecation.py", line 116, in __call__
    response = self.process_response(request, response)
  File "/home/venv/lib/python3.6/site-packages/django/contrib/sessions/middleware.py", line 63, in process_response
    request.session.save()
  File "/home/venv/lib/python3.6/site-packages/django/contrib/sessions/backends/db.py", line 81, in save
    return self.create()
  File "/home/venv/lib/python3.6/site-packages/django/contrib/sessions/backends/db.py", line 55, in create
    self.save(must_create=True)
  File "/home/venv/lib/python3.6/site-packages/django/contrib/sessions/backends/db.py", line 87, in save
    obj.save(force_insert=must_create, force_update=not must_create, using=using)
  File "/home/venv/lib/python3.6/site-packages/django/db/models/base.py", line 754, in save
    force_update=force_update, update_fields=update_fields)
  File "/home/venv/lib/python3.6/site-packages/django/db/models/base.py", line 792, in save_base
    force_update, using, update_fields,
  File "/home/venv/lib/python3.6/site-packages/django/db/models/base.py", line 895, in _save_table
    results = self._do_insert(cls._base_manager, using, fields, returning_fields, raw)
  File "/home/venv/lib/python3.6/site-packages/django/db/models/base.py", line 935, in _do_insert
    using=using, raw=raw,
  File "/home/venv/lib/python3.6/site-packages/django/db/models/manager.py", line 85, in manager_method
    return getattr(self.get_queryset(), name)(*args, **kwargs)
  File "/home/venv/lib/python3.6/site-packages/django/db/models/query.py", line 1249, in _insert
    return query.get_compiler(using=using).execute_sql(returning_fields)
  File "/home/venv/lib/python3.6/site-packages/django/db/models/sql/compiler.py", line 1397, in execute_sql
    cursor.execute(sql, params)
  File "/home/venv/lib/python3.6/site-packages/django/db/backends/utils.py", line 98, in execute
    return super().execute(sql, params)
  File "/home/venv/lib/python3.6/site-packages/django/db/backends/utils.py", line 66, in execute
    return self._execute_with_wrappers(sql, params, many=False, executor=self._execute)
  File "/home/venv/lib/python3.6/site-packages/django/db/backends/utils.py", line 75, in _execute_with_wrappers
    return executor(sql, params, many, context)
  File "/home/venv/lib/python3.6/site-packages/django/db/backends/utils.py", line 84, in _execute
    return self.cursor.execute(sql, params)
  File "/home/venv/lib/python3.6/site-packages/django/db/utils.py", line 90, in __exit__
    raise dj_exc_value.with_traceback(traceback) from exc_value
  File "/home/venv/lib/python3.6/site-packages/django/db/backends/utils.py", line 84, in _execute
    return self.cursor.execute(sql, params)
  File "/home/venv/lib/python3.6/site-packages/django/db/backends/sqlite3/base.py", line 413, in execute
    return Database.Cursor.execute(self, query, params)
django.db.utils.OperationalError: attempt to write a readonly database
Internal Server Error: /
Traceback (most recent call last):
  File "/home/venv/lib/python3.6/site-packages/django/db/backends/utils.py", line 84, in _execute
    return self.cursor.execute(sql, params)
  File "/home/venv/lib/python3.6/site-packages/django/db/backends/sqlite3/base.py", line 413, in execute
    return Database.Cursor.execute(self, query, params)
sqlite3.OperationalError: attempt to write a readonly database

The above exception was the direct cause of the following exception:

Traceback (most recent call last):
  File "/home/venv/lib/python3.6/site-packages/django/core/handlers/exception.py", line 47, in inner
    response = get_response(request)
  File "/home/venv/lib/python3.6/site-packages/django/utils/deprecation.py", line 116, in __call__
    response = self.process_response(request, response)
  File "/home/venv/lib/python3.6/site-packages/django/contrib/sessions/middleware.py", line 63, in process_response
    request.session.save()
  File "/home/venv/lib/python3.6/site-packages/django/contrib/sessions/backends/db.py", line 81, in save
    return self.create()
  File "/home/venv/lib/python3.6/site-packages/django/contrib/sessions/backends/db.py", line 55, in create
    self.save(must_create=True)
  File "/home/venv/lib/python3.6/site-packages/django/contrib/sessions/backends/db.py", line 87, in save
    obj.save(force_insert=must_create, force_update=not must_create, using=using)
  File "/home/venv/lib/python3.6/site-packages/django/db/models/base.py", line 754, in save
    force_update=force_update, update_fields=update_fields)
  File "/home/venv/lib/python3.6/site-packages/django/db/models/base.py", line 792, in save_base
    force_update, using, update_fields,
  File "/home/venv/lib/python3.6/site-packages/django/db/models/base.py", line 895, in _save_table
    results = self._do_insert(cls._base_manager, using, fields, returning_fields, raw)
  File "/home/venv/lib/python3.6/site-packages/django/db/models/base.py", line 935, in _do_insert
    using=using, raw=raw,
  File "/home/venv/lib/python3.6/site-packages/django/db/models/manager.py", line 85, in manager_method
    return getattr(self.get_queryset(), name)(*args, **kwargs)
  File "/home/venv/lib/python3.6/site-packages/django/db/models/query.py", line 1249, in _insert
    return query.get_compiler(using=using).execute_sql(returning_fields)
  File "/home/venv/lib/python3.6/site-packages/django/db/models/sql/compiler.py", line 1397, in execute_sql
    cursor.execute(sql, params)
  File "/home/venv/lib/python3.6/site-packages/django/db/backends/utils.py", line 98, in execute
    return super().execute(sql, params)
  File "/home/venv/lib/python3.6/site-packages/django/db/backends/utils.py", line 66, in execute
    return self._execute_with_wrappers(sql, params, many=False, executor=self._execute)
  File "/home/venv/lib/python3.6/site-packages/django/db/backends/utils.py", line 75, in _execute_with_wrappers
    return executor(sql, params, many, context)
  File "/home/venv/lib/python3.6/site-packages/django/db/backends/utils.py", line 84, in _execute
    return self.cursor.execute(sql, params)
  File "/home/venv/lib/python3.6/site-packages/django/db/utils.py", line 90, in __exit__
    raise dj_exc_value.with_traceback(traceback) from exc_value
  File "/home/venv/lib/python3.6/site-packages/django/db/backends/utils.py", line 84, in _execute
    return self.cursor.execute(sql, params)
  File "/home/venv/lib/python3.6/site-packages/django/db/backends/sqlite3/base.py", line 413, in execute
    return Database.Cursor.execute(self, query, params)
django.db.utils.OperationalError: attempt to write a readonly database
Internal Server Error: /
Traceback (most recent call last):
  File "/home/venv/lib/python3.6/site-packages/django/db/backends/utils.py", line 84, in _execute
    return self.cursor.execute(sql, params)
  File "/home/venv/lib/python3.6/site-packages/django/db/backends/sqlite3/base.py", line 413, in execute
    return Database.Cursor.execute(self, query, params)
sqlite3.OperationalError: attempt to write a readonly database

The above exception was the direct cause of the following exception:

Traceback (most recent call last):
  File "/home/venv/lib/python3.6/site-packages/django/core/handlers/exception.py", line 47, in inner
    response = get_response(request)
  File "/home/venv/lib/python3.6/site-packages/django/utils/deprecation.py", line 116, in __call__
    response = self.process_response(request, response)
  File "/home/venv/lib/python3.6/site-packages/django/contrib/sessions/middleware.py", line 63, in process_response
    request.session.save()
  File "/home/venv/lib/python3.6/site-packages/django/contrib/sessions/backends/db.py", line 81, in save
    return self.create()
  File "/home/venv/lib/python3.6/site-packages/django/contrib/sessions/backends/db.py", line 55, in create
    self.save(must_create=True)
  File "/home/venv/lib/python3.6/site-packages/django/contrib/sessions/backends/db.py", line 87, in save
    obj.save(force_insert=must_create, force_update=not must_create, using=using)
  File "/home/venv/lib/python3.6/site-packages/django/db/models/base.py", line 754, in save
    force_update=force_update, update_fields=update_fields)
  File "/home/venv/lib/python3.6/site-packages/django/db/models/base.py", line 792, in save_base
    force_update, using, update_fields,
  File "/home/venv/lib/python3.6/site-packages/django/db/models/base.py", line 895, in _save_table
    results = self._do_insert(cls._base_manager, using, fields, returning_fields, raw)
  File "/home/venv/lib/python3.6/site-packages/django/db/models/base.py", line 935, in _do_insert
    using=using, raw=raw,
  File "/home/venv/lib/python3.6/site-packages/django/db/models/manager.py", line 85, in manager_method
    return getattr(self.get_queryset(), name)(*args, **kwargs)
  File "/home/venv/lib/python3.6/site-packages/django/db/models/query.py", line 1249, in _insert
    return query.get_compiler(using=using).execute_sql(returning_fields)
  File "/home/venv/lib/python3.6/site-packages/django/db/models/sql/compiler.py", line 1397, in execute_sql
    cursor.execute(sql, params)
  File "/home/venv/lib/python3.6/site-packages/django/db/backends/utils.py", line 98, in execute
    return super().execute(sql, params)
  File "/home/venv/lib/python3.6/site-packages/django/db/backends/utils.py", line 66, in execute
    return self._execute_with_wrappers(sql, params, many=False, executor=self._execute)
  File "/home/venv/lib/python3.6/site-packages/django/db/backends/utils.py", line 75, in _execute_with_wrappers
    return executor(sql, params, many, context)
  File "/home/venv/lib/python3.6/site-packages/django/db/backends/utils.py", line 84, in _execute
    return self.cursor.execute(sql, params)
  File "/home/venv/lib/python3.6/site-packages/django/db/utils.py", line 90, in __exit__
    raise dj_exc_value.with_traceback(traceback) from exc_value
  File "/home/venv/lib/python3.6/site-packages/django/db/backends/utils.py", line 84, in _execute
    return self.cursor.execute(sql, params)
  File "/home/venv/lib/python3.6/site-packages/django/db/backends/sqlite3/base.py", line 413, in execute
    return Database.Cursor.execute(self, query, params)
django.db.utils.OperationalError: attempt to write a readonly database
Internal Server Error: /
Traceback (most recent call last):
  File "/home/venv/lib/python3.6/site-packages/django/db/backends/utils.py", line 84, in _execute
    return self.cursor.execute(sql, params)
  File "/home/venv/lib/python3.6/site-packages/django/db/backends/sqlite3/base.py", line 413, in execute
    return Database.Cursor.execute(self, query, params)
sqlite3.OperationalError: attempt to write a readonly database

The above exception was the direct cause of the following exception:

Traceback (most recent call last):
  File "/home/venv/lib/python3.6/site-packages/django/core/handlers/exception.py", line 47, in inner
    response = get_response(request)
  File "/home/venv/lib/python3.6/site-packages/django/utils/deprecation.py", line 116, in __call__
    response = self.process_response(request, response)
  File "/home/venv/lib/python3.6/site-packages/django/contrib/sessions/middleware.py", line 63, in process_response
    request.session.save()
  File "/home/venv/lib/python3.6/site-packages/django/contrib/sessions/backends/db.py", line 81, in save
    return self.create()
  File "/home/venv/lib/python3.6/site-packages/django/contrib/sessions/backends/db.py", line 55, in create
    self.save(must_create=True)
  File "/home/venv/lib/python3.6/site-packages/django/contrib/sessions/backends/db.py", line 87, in save
    obj.save(force_insert=must_create, force_update=not must_create, using=using)
  File "/home/venv/lib/python3.6/site-packages/django/db/models/base.py", line 754, in save
    force_update=force_update, update_fields=update_fields)
  File "/home/venv/lib/python3.6/site-packages/django/db/models/base.py", line 792, in save_base
    force_update, using, update_fields,
  File "/home/venv/lib/python3.6/site-packages/django/db/models/base.py", line 895, in _save_table
    results = self._do_insert(cls._base_manager, using, fields, returning_fields, raw)
  File "/home/venv/lib/python3.6/site-packages/django/db/models/base.py", line 935, in _do_insert
    using=using, raw=raw,
  File "/home/venv/lib/python3.6/site-packages/django/db/models/manager.py", line 85, in manager_method
    return getattr(self.get_queryset(), name)(*args, **kwargs)
  File "/home/venv/lib/python3.6/site-packages/django/db/models/query.py", line 1249, in _insert
    return query.get_compiler(using=using).execute_sql(returning_fields)
  File "/home/venv/lib/python3.6/site-packages/django/db/models/sql/compiler.py", line 1397, in execute_sql
    cursor.execute(sql, params)
  File "/home/venv/lib/python3.6/site-packages/django/db/backends/utils.py", line 98, in execute
    return super().execute(sql, params)
  File "/home/venv/lib/python3.6/site-packages/django/db/backends/utils.py", line 66, in execute
    return self._execute_with_wrappers(sql, params, many=False, executor=self._execute)
  File "/home/venv/lib/python3.6/site-packages/django/db/backends/utils.py", line 75, in _execute_with_wrappers
    return executor(sql, params, many, context)
  File "/home/venv/lib/python3.6/site-packages/django/db/backends/utils.py", line 84, in _execute
    return self.cursor.execute(sql, params)
  File "/home/venv/lib/python3.6/site-packages/django/db/utils.py", line 90, in __exit__
    raise dj_exc_value.with_traceback(traceback) from exc_value
  File "/home/venv/lib/python3.6/site-packages/django/db/backends/utils.py", line 84, in _execute
    return self.cursor.execute(sql, params)
  File "/home/venv/lib/python3.6/site-packages/django/db/backends/sqlite3/base.py", line 413, in execute
    return Database.Cursor.execute(self, query, params)
django.db.utils.OperationalError: attempt to write a readonly database
Internal Server Error: /
Traceback (most recent call last):
  File "/home/venv/lib/python3.6/site-packages/django/db/backends/utils.py", line 84, in _execute
    return self.cursor.execute(sql, params)
  File "/home/venv/lib/python3.6/site-packages/django/db/backends/sqlite3/base.py", line 413, in execute
    return Database.Cursor.execute(self, query, params)
sqlite3.OperationalError: attempt to write a readonly database

The above exception was the direct cause of the following exception:

Traceback (most recent call last):
  File "/home/venv/lib/python3.6/site-packages/django/core/handlers/exception.py", line 47, in inner
    response = get_response(request)
  File "/home/venv/lib/python3.6/site-packages/django/utils/deprecation.py", line 116, in __call__
    response = self.process_response(request, response)
  File "/home/venv/lib/python3.6/site-packages/django/contrib/sessions/middleware.py", line 63, in process_response
    request.session.save()
  File "/home/venv/lib/python3.6/site-packages/django/contrib/sessions/backends/db.py", line 81, in save
    return self.create()
  File "/home/venv/lib/python3.6/site-packages/django/contrib/sessions/backends/db.py", line 55, in create
    self.save(must_create=True)
  File "/home/venv/lib/python3.6/site-packages/django/contrib/sessions/backends/db.py", line 87, in save
    obj.save(force_insert=must_create, force_update=not must_create, using=using)
  File "/home/venv/lib/python3.6/site-packages/django/db/models/base.py", line 754, in save
    force_update=force_update, update_fields=update_fields)
  File "/home/venv/lib/python3.6/site-packages/django/db/models/base.py", line 792, in save_base
    force_update, using, update_fields,
  File "/home/venv/lib/python3.6/site-packages/django/db/models/base.py", line 895, in _save_table
    results = self._do_insert(cls._base_manager, using, fields, returning_fields, raw)
  File "/home/venv/lib/python3.6/site-packages/django/db/models/base.py", line 935, in _do_insert
    using=using, raw=raw,
  File "/home/venv/lib/python3.6/site-packages/django/db/models/manager.py", line 85, in manager_method
    return getattr(self.get_queryset(), name)(*args, **kwargs)
  File "/home/venv/lib/python3.6/site-packages/django/db/models/query.py", line 1249, in _insert
    return query.get_compiler(using=using).execute_sql(returning_fields)
  File "/home/venv/lib/python3.6/site-packages/django/db/models/sql/compiler.py", line 1397, in execute_sql
    cursor.execute(sql, params)
  File "/home/venv/lib/python3.6/site-packages/django/db/backends/utils.py", line 98, in execute
    return super().execute(sql, params)
  File "/home/venv/lib/python3.6/site-packages/django/db/backends/utils.py", line 66, in execute
    return self._execute_with_wrappers(sql, params, many=False, executor=self._execute)
  File "/home/venv/lib/python3.6/site-packages/django/db/backends/utils.py", line 75, in _execute_with_wrappers
    return executor(sql, params, many, context)
  File "/home/venv/lib/python3.6/site-packages/django/db/backends/utils.py", line 84, in _execute
    return self.cursor.execute(sql, params)
  File "/home/venv/lib/python3.6/site-packages/django/db/utils.py", line 90, in __exit__
    raise dj_exc_value.with_traceback(traceback) from exc_value
  File "/home/venv/lib/python3.6/site-packages/django/db/backends/utils.py", line 84, in _execute
    return self.cursor.execute(sql, params)
  File "/home/venv/lib/python3.6/site-packages/django/db/backends/sqlite3/base.py", line 413, in execute
    return Database.Cursor.execute(self, query, params)
django.db.utils.OperationalError: attempt to write a readonly database
Internal Server Error: /
Traceback (most recent call last):
  File "/home/venv/lib/python3.6/site-packages/django/db/backends/utils.py", line 84, in _execute
    return self.cursor.execute(sql, params)
  File "/home/venv/lib/python3.6/site-packages/django/db/backends/sqlite3/base.py", line 413, in execute
    return Database.Cursor.execute(self, query, params)
sqlite3.OperationalError: attempt to write a readonly database

The above exception was the direct cause of the following exception:

Traceback (most recent call last):
  File "/home/venv/lib/python3.6/site-packages/django/core/handlers/exception.py", line 47, in inner
    response = get_response(request)
  File "/home/venv/lib/python3.6/site-packages/django/utils/deprecation.py", line 116, in __call__
    response = self.process_response(request, response)
  File "/home/venv/lib/python3.6/site-packages/django/contrib/sessions/middleware.py", line 63, in process_response
    request.session.save()
  File "/home/venv/lib/python3.6/site-packages/django/contrib/sessions/backends/db.py", line 81, in save
    return self.create()
  File "/home/venv/lib/python3.6/site-packages/django/contrib/sessions/backends/db.py", line 55, in create
    self.save(must_create=True)
  File "/home/venv/lib/python3.6/site-packages/django/contrib/sessions/backends/db.py", line 87, in save
    obj.save(force_insert=must_create, force_update=not must_create, using=using)
  File "/home/venv/lib/python3.6/site-packages/django/db/models/base.py", line 754, in save
    force_update=force_update, update_fields=update_fields)
  File "/home/venv/lib/python3.6/site-packages/django/db/models/base.py", line 792, in save_base
    force_update, using, update_fields,
  File "/home/venv/lib/python3.6/site-packages/django/db/models/base.py", line 895, in _save_table
    results = self._do_insert(cls._base_manager, using, fields, returning_fields, raw)
  File "/home/venv/lib/python3.6/site-packages/django/db/models/base.py", line 935, in _do_insert
    using=using, raw=raw,
  File "/home/venv/lib/python3.6/site-packages/django/db/models/manager.py", line 85, in manager_method
    return getattr(self.get_queryset(), name)(*args, **kwargs)
  File "/home/venv/lib/python3.6/site-packages/django/db/models/query.py", line 1249, in _insert
    return query.get_compiler(using=using).execute_sql(returning_fields)
  File "/home/venv/lib/python3.6/site-packages/django/db/models/sql/compiler.py", line 1397, in execute_sql
    cursor.execute(sql, params)
  File "/home/venv/lib/python3.6/site-packages/django/db/backends/utils.py", line 98, in execute
    return super().execute(sql, params)
  File "/home/venv/lib/python3.6/site-packages/django/db/backends/utils.py", line 66, in execute
    return self._execute_with_wrappers(sql, params, many=False, executor=self._execute)
  File "/home/venv/lib/python3.6/site-packages/django/db/backends/utils.py", line 75, in _execute_with_wrappers
    return executor(sql, params, many, context)
  File "/home/venv/lib/python3.6/site-packages/django/db/backends/utils.py", line 84, in _execute
    return self.cursor.execute(sql, params)
  File "/home/venv/lib/python3.6/site-packages/django/db/utils.py", line 90, in __exit__
    raise dj_exc_value.with_traceback(traceback) from exc_value
  File "/home/venv/lib/python3.6/site-packages/django/db/backends/utils.py", line 84, in _execute
    return self.cursor.execute(sql, params)
  File "/home/venv/lib/python3.6/site-packages/django/db/backends/sqlite3/base.py", line 413, in execute
    return Database.Cursor.execute(self, query, params)
django.db.utils.OperationalError: attempt to write a readonly database
Internal Server Error: /
Traceback (most recent call last):
  File "/home/venv/lib/python3.6/site-packages/django/db/backends/utils.py", line 84, in _execute
    return self.cursor.execute(sql, params)
  File "/home/venv/lib/python3.6/site-packages/django/db/backends/sqlite3/base.py", line 413, in execute
    return Database.Cursor.execute(self, query, params)
sqlite3.OperationalError: attempt to write a readonly database

The above exception was the direct cause of the following exception:

Traceback (most recent call last):
  File "/home/venv/lib/python3.6/site-packages/django/core/handlers/exception.py", line 47, in inner
    response = get_response(request)
  File "/home/venv/lib/python3.6/site-packages/django/utils/deprecation.py", line 116, in __call__
    response = self.process_response(request, response)
  File "/home/venv/lib/python3.6/site-packages/django/contrib/sessions/middleware.py", line 63, in process_response
    request.session.save()
  File "/home/venv/lib/python3.6/site-packages/django/contrib/sessions/backends/db.py", line 81, in save
    return self.create()
  File "/home/venv/lib/python3.6/site-packages/django/contrib/sessions/backends/db.py", line 55, in create
    self.save(must_create=True)
  File "/home/venv/lib/python3.6/site-packages/django/contrib/sessions/backends/db.py", line 87, in save
    obj.save(force_insert=must_create, force_update=not must_create, using=using)
  File "/home/venv/lib/python3.6/site-packages/django/db/models/base.py", line 754, in save
    force_update=force_update, update_fields=update_fields)
  File "/home/venv/lib/python3.6/site-packages/django/db/models/base.py", line 792, in save_base
    force_update, using, update_fields,
  File "/home/venv/lib/python3.6/site-packages/django/db/models/base.py", line 895, in _save_table
    results = self._do_insert(cls._base_manager, using, fields, returning_fields, raw)
  File "/home/venv/lib/python3.6/site-packages/django/db/models/base.py", line 935, in _do_insert
    using=using, raw=raw,
  File "/home/venv/lib/python3.6/site-packages/django/db/models/manager.py", line 85, in manager_method
    return getattr(self.get_queryset(), name)(*args, **kwargs)
  File "/home/venv/lib/python3.6/site-packages/django/db/models/query.py", line 1249, in _insert
    return query.get_compiler(using=using).execute_sql(returning_fields)
  File "/home/venv/lib/python3.6/site-packages/django/db/models/sql/compiler.py", line 1397, in execute_sql
    cursor.execute(sql, params)
  File "/home/venv/lib/python3.6/site-packages/django/db/backends/utils.py", line 98, in execute
    return super().execute(sql, params)
  File "/home/venv/lib/python3.6/site-packages/django/db/backends/utils.py", line 66, in execute
    return self._execute_with_wrappers(sql, params, many=False, executor=self._execute)
  File "/home/venv/lib/python3.6/site-packages/django/db/backends/utils.py", line 75, in _execute_with_wrappers
    return executor(sql, params, many, context)
  File "/home/venv/lib/python3.6/site-packages/django/db/backends/utils.py", line 84, in _execute
    return self.cursor.execute(sql, params)
  File "/home/venv/lib/python3.6/site-packages/django/db/utils.py", line 90, in __exit__
    raise dj_exc_value.with_traceback(traceback) from exc_value
  File "/home/venv/lib/python3.6/site-packages/django/db/backends/utils.py", line 84, in _execute
    return self.cursor.execute(sql, params)
  File "/home/venv/lib/python3.6/site-packages/django/db/backends/sqlite3/base.py", line 413, in execute
    return Database.Cursor.execute(self, query, params)
django.db.utils.OperationalError: attempt to write a readonly database
Not Found: /delivery/images/bg/dec/section-bg.png
Not Found: /delivery/images/bg/dec/section-bg.png
Not Found: /delivery/images/bg/dec/section-bg.png
Not Found: /delivery/images/bg/dec/section-bg.png
Not Found: /delivery/images/bg/dec/section-bg.png
Not Found: /deliver
Not Found: /delive
Not Found: /deliv
Not Found: /del
Not Found: /de
Not Found: /d
Not Found: /config/getuser
Not Found: /delivery/images/bg/dec/section-bg.png
Not Found: /shop/images/bg/dec/section-bg.png
Not Found: /checkout/images/bg/dec/section-bg.png
Not Found: /item/images/bg/dec/section-bg.png
Not Found: /order-summary/images/bg/dec/section-bg.png
Not Found: /order-summary/images/bg/dec/section-bg.png
Not Found: /order-summary/images/bg/dec/section-bg.png
Not Found: /checkout/images/bg/dec/section-bg.png
Not Found: /shop/images/bg/dec/section-bg.png
Not Found: /shop/images/bg/dec/section-bg.png
/home/venv/lib/python3.6/site-packages/django/views/generic/list.py:88: UnorderedObjectListWarning: Pagination may yield inconsistent results with an unordered object_list: <class 'core.models.Item'> QuerySet.
  allow_empty_first_page=allow_empty_first_page, **kwargs)
Not Found: /wp-login.php
Not Found: /login
Not Found: /jenkins/login
Not Found: /manager/html
Not Found: /wp-login.php
Not Found: /favicon.ico
Not Found: /favicon.ico
Not Found: /favicon.ico
Not Found: /favicon.ico
Not Found: /favicon.ico
Not Found: /favicon.ico
Not Found: /favicon.ico
Not Found: /l.php
Not Found: /index.php
Not Found: /forum.php
Not Found: /forums.php
Not Found: /forums/ajax/render/widget_tabbedcontainer_tab_panel
Not Found: /cgi-bin/php5
Not Found: /webdav/
Not Found: /_query.php
Not Found: /db_pma.php
Not Found: /logon.php
Not Found: /help-e.php
Not Found: /log.php
Not Found: /pmd_online.php
Not Found: /x.php
Not Found: /desktop.ini.php
Not Found: /z.php
Not Found: /lala-dpr.php
Not Found: /muhstik.php
Not Found: /text.php
Not Found: /muhstik2.php
Not Found: /muhstiks.php
Not Found: /muhstik-dpr.php
Not Found: /cmd.php
Not Found: /elrekt.php
Not Found: /joomla/
Not Found: /spider.php
Not Found: /composers.php
Not Found: /images/!.php
Not Found: /hd.php
Not Found: /images/stories/cmd.php
Not Found: /images/stories/filemga.php
Not Found: /up.php
Not Found: /floaw.php
Not Found: /yuyang.php
Not Found: /coonig.php
Not Found: /hhhhhh.php
Not Found: /woshimengmei.php
Not Found: /taisui.php
Not Found: /99.php
Not Found: /1ts.php
Not Found: /haiyan.php
Not Found: /xiu.php
Not Found: /cms/wp-content/plugins/wp-file-manager/readme.txt
Not Found: /Blog/wp-content/plugins/wp-file-manager/readme.txt
Not Found: /dev/wp-content/plugins/wp-file-manager/readme.txt
Not Found: /beita.php
Not Found: /xw.php
Not Found: /xw1.php
Not Found: /weaver/bsh.servlet.BshServlet
Not Found: /joomla/
Not Found: /phpMyAdmin/index.php
Not Found: /mysql/index.php
Not Found: /mysql-admin/index.php
Not Found: /mysql_admin/index.php
Not Found: /phpmyadmin2/index.php
Not Found: /phpMyAdmin4.8.1/index.php
Not Found: /phpMyAdmin4.8.5/index.php
Not Found: /myadmin/index.php
Not Found: /www/phpMyAdmin/index.php
Not Found: /tools/phpMyAdmin/index.php
Not Found: /phpmyadmin-old/index.php
Not Found: /typo3/phpmyadmin/index.php
Not Found: /phpMyAdmin__/index.php
Not Found: /phpmyadm1n/index.php
Not Found: /phpMyadmi/index.php
Not Found: /MyAdmin/index.php
Not Found: /phpMyAdmin1/index.php
Not Found: /phpMydmin/index.php
Not Found: /phpMyAdmin._2/index.php
Not Found: /phpmyadmin2222/index.php
Not Found: /phpMyAdmin_111/index.php
Not Found: /phpMyAdmln/index.php
Not Found: /phpMyAdmin_ai/index.php
Not Found: /__phpMyAdmin/index.php
Not Found: /program/index.php
Not Found: /phppma/index.php
Not Found: /phpmy/index.php
Not Found: /mysql/sqlmanager/index.php
Not Found: /SQL/index.php
Not Found: /jenkins/login
Not Found: /favicon.ico
Not Found: /favicon.ico
Not Found: /favicon.ico
Not Found: /favicon.ico
Not Found: /favicon.ico
[2021-02-18 00:38:24 +0200] [16306] [INFO] Handling signal: term
[2021-02-17 22:38:24 +0000] [16310] [INFO] Worker exiting (pid: 16310)
<WSGIRequest: GET '/order-summary/'>
4
[2021-02-17 22:38:24 +0000] [16312] [INFO] Worker exiting (pid: 16312)
<WSGIRequest: GET '/order-summary/'>
4
test
non existing

added

<WSGIRequest: GET '/order-summary/'>
4
[2021-02-17 22:38:24 +0000] [16313] [INFO] Worker exiting (pid: 16313)
<WSGIRequest: GET '/order-summary/?csrfmiddlewaretoken=0UjhCB0KXjBza5vgcFI8JKzHfiaQXnMeVMjOEHWLuu7hKkeiKTCSXlmXUS5naWAv&cartcoupon=test'>
4
[2021-02-18 00:38:24 +0200] [16306] [INFO] Shutting down: Master
[2021-02-18 00:38:24 +0200] [20924] [INFO] Starting gunicorn 20.0.4
[2021-02-18 00:38:24 +0200] [20924] [INFO] Listening at: http://127.0.0.1:8000 (20924)
[2021-02-18 00:38:24 +0200] [20924] [INFO] Using worker: sync
[2021-02-18 00:38:24 +0200] [20927] [INFO] Booting worker with pid: 20927
[2021-02-18 00:38:24 +0200] [20929] [INFO] Booting worker with pid: 20929
[2021-02-18 00:38:24 +0200] [20930] [INFO] Booting worker with pid: 20930
Not Found: /favicon.ico
Not Found: /favicon.ico
Not Found: /config/getuser
[2021-02-18 01:03:02 +0200] [20924] [INFO] Handling signal: term
[2021-02-17 23:03:02 +0000] [20927] [INFO] Worker exiting (pid: 20927)
[2021-02-17 23:03:02 +0000] [20930] [INFO] Worker exiting (pid: 20930)
[2021-02-17 23:03:02 +0000] [20929] [INFO] Worker exiting (pid: 20929)
[2021-02-18 01:03:02 +0200] [20924] [INFO] Shutting down: Master
[2021-02-18 01:03:02 +0200] [21238] [INFO] Starting gunicorn 20.0.4
[2021-02-18 01:03:02 +0200] [21238] [INFO] Listening at: http://127.0.0.1:8000 (21238)
[2021-02-18 01:03:02 +0200] [21238] [INFO] Using worker: sync
[2021-02-18 01:03:02 +0200] [21241] [INFO] Booting worker with pid: 21241
[2021-02-18 01:03:02 +0200] [21242] [INFO] Booting worker with pid: 21242
[2021-02-18 01:03:03 +0200] [21245] [INFO] Booting worker with pid: 21245
Not Found: /shop/images/bg/dec/section-bg.png
Not Found: /shop/images/bg/dec/section-bg.png
[2021-02-18 02:01:37 +0200] [21238] [INFO] Handling signal: term
[2021-02-18 00:01:37 +0000] [21241] [INFO] Worker exiting (pid: 21241)

 SessionOrder matching query does not exist.


 SessionOrder matching query does not exist.

/home/venv/lib/python3.6/site-packages/django/views/generic/list.py:88: UnorderedObjectListWarning: Pagination may yield inconsistent results with an unordered object_list: <class 'core.models.Item'> QuerySet.
  allow_empty_first_page=allow_empty_first_page, **kwargs)
[2021-02-18 00:01:37 +0000] [21242] [INFO] Worker exiting (pid: 21242)

 SessionOrder matching query does not exist.


 SessionOrder matching query does not exist.

[2021-02-18 00:01:37 +0000] [21245] [INFO] Worker exiting (pid: 21245)
[2021-02-18 02:01:37 +0200] [21238] [INFO] Shutting down: Master
[2021-02-18 02:01:37 +0200] [21477] [INFO] Starting gunicorn 20.0.4
[2021-02-18 02:01:37 +0200] [21477] [INFO] Listening at: http://127.0.0.1:8000 (21477)
[2021-02-18 02:01:37 +0200] [21477] [INFO] Using worker: sync
[2021-02-18 02:01:37 +0200] [21480] [INFO] Booting worker with pid: 21480
[2021-02-18 02:01:37 +0200] [21482] [INFO] Booting worker with pid: 21482
[2021-02-18 02:01:37 +0200] [21484] [INFO] Booting worker with pid: 21484
[2021-02-18 02:03:05 +0200] [21477] [INFO] Handling signal: term
[2021-02-18 00:03:05 +0000] [21482] [INFO] Worker exiting (pid: 21482)
[2021-02-18 00:03:05 +0000] [21480] [INFO] Worker exiting (pid: 21480)
[2021-02-18 00:03:05 +0000] [21484] [INFO] Worker exiting (pid: 21484)
[2021-02-18 02:03:05 +0200] [21477] [INFO] Shutting down: Master
[2021-02-18 02:03:05 +0200] [21489] [INFO] Starting gunicorn 20.0.4
[2021-02-18 02:03:05 +0200] [21489] [INFO] Listening at: http://127.0.0.1:8000 (21489)
[2021-02-18 02:03:05 +0200] [21489] [INFO] Using worker: sync
[2021-02-18 02:03:05 +0200] [21492] [INFO] Booting worker with pid: 21492
[2021-02-18 02:03:05 +0200] [21494] [INFO] Booting worker with pid: 21494
[2021-02-18 02:03:05 +0200] [21495] [INFO] Booting worker with pid: 21495
Not Found: /favicon.ico
Not Found: /vendor/phpunit/phpunit/src/Util/PHP/eval-stdin.php
Not Found: /vendor/phpunit/phpunit/src/Util/PHP/eval-stdin.php
Not Found: /solr/admin/info/system
Not Found: /Autodiscover/Autodiscover.xml
Not Found: /index.php
Not Found: /console/
Not Found: /_ignition/execute-solution
Not Found: /wp-content/plugins/wp-file-manager/readme.txt
Not Found: /api/jsonws/invoke
Not Found: /favicon.ico
Not Found: /cgi-bin/luci
Not Found: /config/getuser
Not Found: /favicon.ico
Not Found: /delivery/images/bg/dec/section-bg.png
Not Found: /favicon.ico
Not Found: /shop/images/bg/dec/section-bg.png
Not Found: /GponForm/diag_Form
/home/venv/lib/python3.6/site-packages/django/views/generic/list.py:88: UnorderedObjectListWarning: Pagination may yield inconsistent results with an unordered object_list: <class 'core.models.Item'> QuerySet.
  allow_empty_first_page=allow_empty_first_page, **kwargs)
Not Found: /shop/images/bg/dec/section-bg.png
Not Found: /favicon.ico
Not Found: /shop/images/bg/dec/section-bg.png
Not Found: /favicon.ico
Not Found: /config/getuser
Not Found: /0bef
Not Found: /shell
Not Found: /vendor/phpunit/phpunit/src/Util/PHP/eval-stdin.php
Not Found: /api/jsonws/invoke
Not Found: /vendor/phpunit/phpunit/src/Util/PHP/eval-stdin.php
Not Found: /solr/admin/info/system
Not Found: /index.php
Not Found: /wp-content/plugins/wp-file-manager/readme.txt
Not Found: /console/
Not Found: /Autodiscover/Autodiscover.xml
Not Found: /_ignition/execute-solution
Not Found: /actuator/health
Not Found: /login
Not Found: /jenkins/login
Not Found: /manager/html
Not Found: /wp-login.php
Not Found: /favicon.ico
Not Found: /shop/images/bg/dec/section-bg.png
Not Found: /shop/images/bg/dec/section-bg.png
